Workbook
Name _cum3: '[1]BALANCE N'!$L:$L
Name _cum4: '[1]BALANCE N'!$M:$M
Name _dFin: 42735
Name _mc1: 'Balance N-1'!$N$3:$N$2201
Name _md1: 'Balance N-1'!$M$3:$M$2201
Name _sfc1: 'Balance N-1'!$P$3:$P$2201
Name _sfd1: 'Balance N-1'!$O$3:$O$2201
Name _sic1: 'Balance N-1'!$L$3:$L$2201
Name _sid1: 'Balance N-1'!$K$3:$K$2201
Name _soNumFisc: 3201201523617
Name _soSigle: "PYTHAGORE CONSULTAN"
Name Cptes: 'Balance N'!$I$3:$I$2201
Name Cptes1: 'Balance N-1'!$I$3:$I$2201
Name Exercice: 'INFORMATIONS GENERALES'!$B$3
Name mc: 'Balance N'!$N$3:$N$2201
Name md: 'Balance N'!$M$3:$M$2201
Name sfc: 'Balance N'!$P$3:$P$2201
Name sfd: 'Balance N'!$O$3:$O$2201
Name sic: 'Balance N'!$L$3:$L$2201
Name sid: 'Balance N'!$K$3:$K$2201

Sheet Présentation
A1: États financiers des projets de développement et assimilés (Systèmes normal)
A3: Contenu des états financiers
A4: Les états financiers des projets de développement et assimilés comprennent :
A5: · Le tableau emploies ressources ;
A6: · Le tableau d’exécution du budgétaire ;
A7: · Le tableau de réconciliation de trésorerie ;
A8: · Le bilan ;
A9: · Le compte d’exploitation ;
A10: · Et les Notes annexes.
A11: ATTENTION
A12: Compte d’exploitation : le résultat dégagé par les opérations est intitulé : solde des opérations de l’exercice qui doit être nul.
A13: Notes annexes: Les Notes non documentées ne doivent pas être jointes aux états financiers. Leur contenu peut être amélioré par les entités. Par ailleurs, dans une note, les lignes non chiffrées doivent être supprimées.
A14: Par exemple, dans la note 17 Services extérieurs, lorsque la ligne sous-traitance générale n’est pas chiffrée, elle ne doit pas figurer dans cette note.

Sheet Plan Comptable
F1: SYCEBNL (Système Comptable des Entités à But Non Lucratif)
F3: CLASSE 1: COMPTES DE RESSOURCES DURABLES
F4: 10. | G4: DOTATION
F5: 101 | G5: Dotationb non consomptible sans droit de reprise
F6: 1011 | G6: en numéraire
F7: 1015 | G7: en nature
F8: 102 | G8: Dotationb non consomptible avec droit de reprise
F9: 1021 | G9: en numéraire
F10: 1025 | G10: en nature
F11: 103 | G11: Droit d'entrée
F12: 104 | G12: Dotation consomptible
F13: 1041 | G13: Dotation consomptible
F14: 1049 | G14: Dotation consomptible inscrite au compte de résultat
F15: 106 | G15: Ecarts de réévaluation
F16: 1061 | G16: Ecarts de réévaluation sur des biens sans droit de reprise
... F21: 10622 | G21: Ecarts de réévaluation sur les biens avec droit de reprise-immobilisations financières
F22: 11. | G22: RESERVES
F23: 112 | G23: Réserves statutaires ou contactuelles
F24: 118 | G24: Autres réserves
F25: 12. | G25: REPORT A NOUVEAU
F26: 121 | G26: Rapport à nouveau des excédents
F27: 1211 | G27: Repport à nouveau des excédents-résultat*
F28: 1213 | G28: Repport à nouveau des excédents-changement de méthode comptamble*
F29: 1214 | G29: Report à nouveau des excédents-corrections d'erreurs significatives*
F30: 1218 | G30: Report à nouveau des excédents-autres reports*
F31: 128 | G31: Résultat net en instance d'affectation
F32: 1281 | G32: Résultat net en instance d'affectation:Excédent*
F33: 1289 | G33: Résultat net en instance d'affectation:Déficit*
F34: 129 | G34: Report à nouveau des déficits
F35: 1291 | G35: Report à nouveau des déficits-résultat*
F36: 1293 | G36: Report à nouveau des déficits -changement de méthode comptable*
F37: 1294 | G37: Report à nouveau des déficits-corrections d'erreurs significatives*
F38: 1298 | G38: Report à nouveau des déficits-autres reports*
F39: 13. | G39: RESULTAT NET DE L'EXERCICE
F40: 131 | G40: Excédent de l'exercice
F41: 139 | G41: Déficit de l'exercice
F42: 14. | G42: SUBVENTIONS D'INVESTISSEMENT
F43: 141 | G43: Subventions d'équipement
F44: 1411 | G44: Etat
F45: 1412 | G45: Regions
...

Sheet MENU PRINCIPAL
B1: N° | C1: INTITULE | D1: RENVOIE | E1: N° | F1: INTITULE | G1: RENVOIE
B2: 1 | C2: Informations générales | D2: Entité | E2: =B27+1 -> 27 | F2: Subventions | G2: NOTE 10
B3: 2 | C3: Balance générale de l'exercice N | D3: Balance N | E3: =E2+1 -> 28 | F3: Dettes financières et ressources assimilées | G3: NOTE 11
B4: 3 | C4: Balance générale de l'exercice N-1 | D4: Balance N-1 | E4: =E3+1 -> 29 | F4: Dettes fournisseurs et assimilées, dettes fiscales et sociales | G4: NOTE 12
B5: 4 | C5: Contrôle d'équilibre des balances et bilans | D5: Contrôles | E5: =E4+1 -> 30 | F5: Banques, crédit d'escompte et de trésorerie | G5: NOTE 13
B6: 5 | C6: Page de couveture des états financiers annuels | D6: Couverture | E6: =E5+1 -> 31 | F6: Revenus et autres produits | G6: NOTE 14
B7: 6 | C7: Page de garde des états financiers annuels | D7: Page garde | E7: =E6+1 -> 32 | F7: Achats | G7: NOTE 15
B8: 7 | C8: Fiche d'identification et renseignements divers 1 | D8: Fiche R1 | E8: =E7+1 -> 33 | F8: Transports | G8: NOTE 16
B9: 8 | C9: Fiche d'identification et renseignements divers 2 | D9: Fiche R2 | E9: =E8+1 -> 34 | F9: Services extérieurs | G9: NOTE 17
B10: 9 | C10: Tableau emplois-ressources | D10: TER | E10: =E9+1 -> 35 | F10: Impôts et taxes | G10: NOTE 18
B11: 10 | C11: Tableau de reconciliation de trésorerie | D11: TRC | E11: =E10+1 -> 36 | F11: Autres charges | G11: NOTE 19
B12: 11 | C12: Tableau d'exécution budgétaire | D12: TEB | E12: =E11+1 -> 37 | F12: Charges de personnel | G12: NOTE 20A
B13: 12 | C13: Bilan en paysage | D13: Bilan | E13: =E12+1 -> 38 | F13: Effectifs, masse salariale et personnel extérieur | G13: NOTE 20B | K13: AFFICHER OU MASQUER NOTES
B14: 13 | C14: Bilan-Actif | D14: Bilan-Actif | E14: =E13+1 -> 39 | F14: Charges et revenus financiers | G14: NOTE 21 | K14: VALEURS | L14: NOTES
B15: 14 | C15: Bilan-Passif | D15: Bilan-Passif | E15: =E14+1 -> 40 | F15: Dotations et charges pour provisions | G15: NOTE 22 | K15: =[2]R4!L9 -> 0 | L15: NOTE 1
B16: 15 | C16: Compte de résultat | D16: Résultat | E16: =E15+1 -> 41 | F16: Autres charges et produits HAO | G16: NOTE 23 | K16: =[2]R4!L10 -> 0 | L16: NOTE 2
B17: 16 | C17: Fiche recapitulative des Notes annexes présentées | D17: Fiche R3 | E17: =E16+1 -> 42 | F17: Tableau d'exécution budgétaire | G17: NOTE 24 | K17: =[2]R4!L11 -> 1 | L17: NOTE 3A
B18: 17 | C18: Informations obligatoires | D18: NOTE 1 | E18: =E17+1 -> 43 | F18: Table des commentaires | G18: COMMENTAIRE | K18: =[2]R4!L12 -> 0 | L18: NOTE 3B
B19: 18 | C19: Informations spécifiques | D19: NOTE 2 | E19: =E18+1 -> 44 | F19: Etats supplémentaires | G19: GARDE (DGI-INS) | K19: =[2]R4!L13 -> 1 | L19: NOTE 3C
B20: 19 | C20: Immobilisations brutes | D20: NOTE 3A | E20: =E19+1 -> 45 | F20: Fiche récapitulative des états supplémentaires DGI & INS | G20: NOTES DGI - INS | K20: =[2]R4!L14 -> 0 | L20: NOTE 3C BIS
B21: 20 | C21: Biens pris en location acquisition | D21: NOTE 3B | E21: =E20+1 -> 46 | F21: Etat complementaire DGI/Comptabilite Nationale | G21: COMP-CHARGES | K21: =[2]R4!L15 -> 0 | L21: NOTE 3D
B22: 21 | C22: Actif circulant et dettes circulantes HAO | D22: NOTE 4 | E22: =E21+1 -> 47 | F22: Etat complementaire DGI/Comptabilite Nationale | G22: COMP-TVA | K22: =[2]R4!L16 -> 1 | L22: NOTE 3E
B23: 22 | C23: Stocks et encours | D23: NOTE 5 | E23: =E22+1 -> 48 | F23: Etat complementaire DGI/Comptabilite Nationale | G23: COMP-TVA (2) | K23: =[2]R4!L17 -> 1 | L23: NOTE 4
B24: 23 | C24: Clients-usagers et autres créances | D24: NOTE 6 | E24: =E23+1 -> 49 | F24: Tableau des amortissements et inventaire des immobilisations | G24: SUPPL1 | K24: =[2]R4!L18 -> 1 | L24: NOTE 5
B25: 24 | C25: Disponibilités | D25: NOTE 7 | E25: =E24+1 -> 50 | F25: Détail des frais accessoires sur achats | G25: SUPPL2 | K25: =[2]R4!L19 -> 1 | L25: NOTE 6
B26: 25 | C26: Ecarts de conversion et transferts de charges | D26: NOTE 8 | E26: =E25+1 -> 51 | F26: Détail des avantages en nature et en espèces imposes (Pl) | G26: SUPPL3 | K26: =[2]R4!L20 -> 1 | L26: NOTE 7
B27: 26 | C27: Fonds du bailleur | D27: NOTE 9 | E27: =E26+1 -> 52 | K27: =[2]R4!L21 -> 1 | L27: NOTE 8
K28: =[2]R4!L40 -> 1 | L28: NOTE 20
K29: =[2]R4!L41 -> 1 | L29: NOTE 21
K30: =[2]R4!L42 -> 1 | L30: NOTE 22
K31: =[2]R4!L43 -> 1 | L31: NOTE 23
K32: =[2]R4!L44 -> 1 | L32: NOTE 24
K33: =[2]R4!L45 -> 1 | L33: NOTE 25
K34: =[2]R4!L46 -> 1 | L34: NOTE 26
K35: =[2]R4!L47 -> 1 | L35: NOTE 27A
K36: =[2]R4!L48 -> 0 | L36: NOTE 27B
K37: =[2]R4!L49 -> 1 | L37: NOTE 28
K38: =[2]R4!L50 -> 1 | L38: NOTE 29
K39: =[2]R4!L51 -> 0 | L39: NOTE 30
... K44: =[2]R4!L56 -> 0 | L44: NOTE 35
...

Sheet INFORMATIONS GENERALES
AD1: =IF(YEAR(U9)>1900,U9,"") -> 45657 | AE1: =MONTH(I15) -> 1
AD2: =IF(YEAR(U9)>1900,EDATE(U9,3),"") -> 45747 | AE2: =YEAR(I15) -> 1900
AD3: Date d'arrêt | AE3: =IF(AE1>=7,AE2+1,AE2) -> 1900
AE4: Date de Création
C7: INFORMATIONS GENERALES DE L'ENTITE | AH7: =IF(AND([2]RESULTAT!I18<>0,E62<>0,E62<>""),(Z30)/[2]RESULTAT!I18,0) -> 0
AH8: =IF(AND([2]RESULTAT!J18<>0,E62<>0,E62<>""),(Z56/E62)/[2]RESULTAT!J18,0) -> 0
C9: ZA | E9: EXERCICE COMPTABLE : | O9: DU: | P9: 45292 | T9: AU: | U9: 45657
Z10: 1900 | AA10: =IF(Z10>1900,Z10,"N") -> N
C11: ZB | D11: DATE D'ARRETE EFFECTIF DES COMPTES : | J11: 45747 | Z11: 1900 | AA11: =IF(Z11>1900,Z11,"N-1") -> N-1
C13: ZC | D13: EXERCICE PRECEDENT CLOS LE : | J13: 45657 | M13: ZD | O13: DUREE EXERCICE PRECEDENT EN MOIS : | W13: 12
C15: ZE | E15: 10 | L15: ZF
E16: Greffe | F16: N°Registre du Commerce | I16: Date de Création | M16: N° Répertoire des entités
C18: ZG | G18: ZH | R18: ZI | S18: A0101
E19: N° de caisse sociale | H19: N° Code Importateur
C21: ZJ | E21: DSO Services | L21: DSO Services
E22: Désignation de l'entité | L22: Sigle
C24: ZK | E24: 76191918 | G24: scheckoumard@gmail.com | K24: 01 | L24: 13 | N24: Bobo-Dioulasso
E25: N° de téléphone | G25: Adresse email | K25: Code | L25: BP | N25: Ville
S26: Code activités
C28: ZL | E28: Rue Alphamoi Djénèpo, secteur 01, Bobo-Dioulasso, Burkina Faso
E29: Adresse géographique complète (Immeuble, rue, quartier, ville, pays)
C31: ZM | R31: 1
E32: Désignation précise de l'activité principale exercée par l'entité | R32: % Capacité production utile
AG33: 0
C34: ZO
E35: Nom | G35: Adresse Personne à contacter en cas de demande | K35: Téléphone | M35: Adresse e-mail | U35: Qualité
C37: ZP
E38: Nom | G38: Adresse | M38: Téléphone | Q38: Adresse e-mail
E39: Salarié de l'entité ou professionnel comptable inscrit à l'Ordre des Experts-comptables ayant établi les états financiers
C41: ZQ
E42: Nom, adresse, téléphone, e-mail et numéro d'inscription à l'Ordre des Experts-comptables de l'Expert comptable ayant délivré l'attestation de visa
C45: ZR
E46: Nom, adresse, téléphone, e-mail et numéro d'inscription à l'Ordre des Experts-comptables de l'Expert comptablble ayant délivré l'attestation d'exécution de la mission du commissariat aux comptes
C50: ZS | S50: Oui
P51: Etats financiers approuvés par l'Assemblée Générale (cocher la case)
O53: NCC | P53: 00000101A
E54: Centre d'impôt | I54: Commune | P54: Numéro de conte contribuable
E56: Personne morale | G56: SARL | I56: Réel normal | J56: Côte d'Ivoire | O56: NTD | P56: Néant
E57: Type de personne | G57: Forme juridique | I57: Régime fiscal | J57: Pays du siège social | P57: Numéro de télédéclarant
E59: Impôt BIC | G59: 0.25 | J59: 0.005 | L59: ZW
...

Sheet Balance N
I1: CPTE | J1: INTITULES DES COMPTES | K1: MOUV.N-1. DEBIT | L1: MOUV.N-1.CREBIT | M1: MOUV.N DEBIT | N1: MOUV.N CREDIT | O1: S.F. DEBIT | P1: S.F. CREDIT
K2: =SUM(sid) -> 0 | L2: =SUM(sic) -> 0 | M2: =SUM(md) -> 0 | N2: =SUM(mc) -> 0 | O2: =SUM(sfd) -> 0 | P2: =SUM(sfc) -> 0
A3: =IF(Cptes="","",LEFT(Cptes,2)) | B3: =IF(Cptes="","",LEFT(Cptes,3)) | C3: =IF(Cptes="","",LEFT(Cptes,4)) | D3: =IF(Cptes="","",LEFT(Cptes,5)) | E3: =IF(Cptes="","",LEFT(Cptes,6)) | F3: =IF(Cptes="","",LEFT(Cptes,7)) | G3: =IF(Cptes="","",LEFT(Cptes,7)) | H3: =IF(Cptes="","",LEFT(Cptes,7))
A4: =IF(Cptes="","",LEFT(Cptes,2)) | B4: =IF(Cptes="","",LEFT(Cptes,3)) | C4: =IF(Cptes="","",LEFT(Cptes,4)) | D4: =IF(Cptes="","",LEFT(Cptes,5)) | E4: =IF(Cptes="","",LEFT(Cptes,6)) | F4: =IF(Cptes="","",LEFT(Cptes,7)) | G4: =IF(Cptes="","",LEFT(Cptes,7)) | H4: =IF(Cptes="","",LEFT(Cptes,7))
A5: =IF(Cptes="","",LEFT(Cptes,2)) | B5: =IF(Cptes="","",LEFT(Cptes,3)) | C5: =IF(Cptes="","",LEFT(Cptes,4)) | D5: =IF(Cptes="","",LEFT(Cptes,5)) | E5: =IF(Cptes="","",LEFT(Cptes,6)) | F5: =IF(Cptes="","",LEFT(Cptes,7)) | G5: =IF(Cptes="","",LEFT(Cptes,7)) | H5: =IF(Cptes="","",LEFT(Cptes,7))
A6: =IF(Cptes="","",LEFT(Cptes,2)) | B6: =IF(Cptes="","",LEFT(Cptes,3)) | C6: =IF(Cptes="","",LEFT(Cptes,4)) | D6: =IF(Cptes="","",LEFT(Cptes,5)) | E6: =IF(Cptes="","",LEFT(Cptes,6)) | F6: =IF(Cptes="","",LEFT(Cptes,7)) | G6: =IF(Cptes="","",LEFT(Cptes,7)) | H6: =IF(Cptes="","",LEFT(Cptes,7))
A7: =IF(Cptes="","",LEFT(Cptes,2)) | B7: =IF(Cptes="","",LEFT(Cptes,3)) | C7: =IF(Cptes="","",LEFT(Cptes,4)) | D7: =IF(Cptes="","",LEFT(Cptes,5)) | E7: =IF(Cptes="","",LEFT(Cptes,6)) | F7: =IF(Cptes="","",LEFT(Cptes,7)) | G7: =IF(Cptes="","",LEFT(Cptes,7)) | H7: =IF(Cptes="","",LEFT(Cptes,7))
A8: =IF(Cptes="","",LEFT(Cptes,2)) | B8: =IF(Cptes="","",LEFT(Cptes,3)) | C8: =IF(Cptes="","",LEFT(Cptes,4)) | D8: =IF(Cptes="","",LEFT(Cptes,5)) | E8: =IF(Cptes="","",LEFT(Cptes,6)) | F8: =IF(Cptes="","",LEFT(Cptes,7)) | G8: =IF(Cptes="","",LEFT(Cptes,7)) | H8: =IF(Cptes="","",LEFT(Cptes,7))
A9: =IF(Cptes="","",LEFT(Cptes,2)) | B9: =IF(Cptes="","",LEFT(Cptes,3)) | C9: =IF(Cptes="","",LEFT(Cptes,4)) | D9: =IF(Cptes="","",LEFT(Cptes,5)) | E9: =IF(Cptes="","",LEFT(Cptes,6)) | F9: =IF(Cptes="","",LEFT(Cptes,7)) | G9: =IF(Cptes="","",LEFT(Cptes,7)) | H9: =IF(Cptes="","",LEFT(Cptes,7))
A10: =IF(Cptes="","",LEFT(Cptes,2)) | B10: =IF(Cptes="","",LEFT(Cptes,3)) | C10: =IF(Cptes="","",LEFT(Cptes,4)) | D10: =IF(Cptes="","",LEFT(Cptes,5)) | E10: =IF(Cptes="","",LEFT(Cptes,6)) | F10: =IF(Cptes="","",LEFT(Cptes,7)) | G10: =IF(Cptes="","",LEFT(Cptes,7)) | H10: =IF(Cptes="","",LEFT(Cptes,7))
A11: =IF(Cptes="","",LEFT(Cptes,2)) | B11: =IF(Cptes="","",LEFT(Cptes,3)) | C11: =IF(Cptes="","",LEFT(Cptes,4)) | D11: =IF(Cptes="","",LEFT(Cptes,5)) | E11: =IF(Cptes="","",LEFT(Cptes,6)) | F11: =IF(Cptes="","",LEFT(Cptes,7)) | G11: =IF(Cptes="","",LEFT(Cptes,7)) | H11: =IF(Cptes="","",LEFT(Cptes,7))
A12: =IF(Cptes="","",LEFT(Cptes,2)) | B12: =IF(Cptes="","",LEFT(Cptes,3)) | C12: =IF(Cptes="","",LEFT(Cptes,4)) | D12: =IF(Cptes="","",LEFT(Cptes,5)) | E12: =IF(Cptes="","",LEFT(Cptes,6)) | F12: =IF(Cptes="","",LEFT(Cptes,7)) | G12: =IF(Cptes="","",LEFT(Cptes,7)) | H12: =IF(Cptes="","",LEFT(Cptes,7))
A13: =IF(Cptes="","",LEFT(Cptes,2)) | B13: =IF(Cptes="","",LEFT(Cptes,3)) | C13: =IF(Cptes="","",LEFT(Cptes,4)) | D13: =IF(Cptes="","",LEFT(Cptes,5)) | E13: =IF(Cptes="","",LEFT(Cptes,6)) | F13: =IF(Cptes="","",LEFT(Cptes,7)) | G13: =IF(Cptes="","",LEFT(Cptes,7)) | H13: =IF(Cptes="","",LEFT(Cptes,7))
A14: =IF(Cptes="","",LEFT(Cptes,2)) | B14: =IF(Cptes="","",LEFT(Cptes,3)) | C14: =IF(Cptes="","",LEFT(Cptes,4)) | D14: =IF(Cptes="","",LEFT(Cptes,5)) | E14: =IF(Cptes="","",LEFT(Cptes,6)) | F14: =IF(Cptes="","",LEFT(Cptes,7)) | G14: =IF(Cptes="","",LEFT(Cptes,7)) | H14: =IF(Cptes="","",LEFT(Cptes,7))
... A2201: =IF(Cptes="","",LEFT(Cptes,2)) | B2201: =IF(Cptes="","",LEFT(Cptes,3)) | C2201: =IF(Cptes="","",LEFT(Cptes,4)) | D2201: =IF(Cptes="","",LEFT(Cptes,5)) | E2201: =IF(Cptes="","",LEFT(Cptes,6)) | F2201: =IF(Cptes="","",LEFT(Cptes,7)) | G2201: =IF(Cptes="","",LEFT(Cptes,7)) | H2201: =IF(Cptes="","",LEFT(Cptes,7))

Sheet Balance N-1
I1: CPTE | J1: INTITULES DES COMPTES | K1: MOUV.N-2. DEBIT | L1: MOUV.N-2.CREBIT | M1: MOUV.N-1 DEBIT | N1: MOUV.N-1 CREDIT | O1: S.F. DEBIT N-1 | P1: S.F. CREDIT N-1
K2: =SUM(_sid1) -> 0 | L2: =SUM(_sic1) -> 0 | M2: =SUM(_md1) -> 0 | N2: =SUM(_mc1) -> 0 | O2: =SUM(_sfd1) -> 0 | P2: =SUM(_sfc1) -> 0
A3: =IF(Cptes1="","",LEFT(Cptes1,2)) | B3: =IF(Cptes1="","",LEFT(Cptes1,3)) | C3: =IF(Cptes1="","",LEFT(Cptes1,4)) | D3: =IF(Cptes1="","",LEFT(Cptes1,5)) | E3: =IF(Cptes1="","",LEFT(Cptes1,6)) | F3: =IF(Cptes1="","",LEFT(Cptes1,7)) | G3: =IF(Cptes1="","",LEFT(Cptes1,7)) | H3: =IF(Cptes1="","",LEFT(Cptes1,7))
A4: =IF(Cptes1="","",LEFT(Cptes1,2)) | B4: =IF(Cptes1="","",LEFT(Cptes1,3)) | C4: =IF(Cptes1="","",LEFT(Cptes1,4)) | D4: =IF(Cptes1="","",LEFT(Cptes1,5)) | E4: =IF(Cptes1="","",LEFT(Cptes1,6)) | F4: =IF(Cptes1="","",LEFT(Cptes1,7)) | G4: =IF(Cptes1="","",LEFT(Cptes1,7)) | H4: =IF(Cptes1="","",LEFT(Cptes1,7))
A5: =IF(Cptes1="","",LEFT(Cptes1,2)) | B5: =IF(Cptes1="","",LEFT(Cptes1,3)) | C5: =IF(Cptes1="","",LEFT(Cptes1,4)) | D5: =IF(Cptes1="","",LEFT(Cptes1,5)) | E5: =IF(Cptes1="","",LEFT(Cptes1,6)) | F5: =IF(Cptes1="","",LEFT(Cptes1,7)) | G5: =IF(Cptes1="","",LEFT(Cptes1,7)) | H5: =IF(Cptes1="","",LEFT(Cptes1,7))
A6: =IF(Cptes1="","",LEFT(Cptes1,2)) | B6: =IF(Cptes1="","",LEFT(Cptes1,3)) | C6: =IF(Cptes1="","",LEFT(Cptes1,4)) | D6: =IF(Cptes1="","",LEFT(Cptes1,5)) | E6: =IF(Cptes1="","",LEFT(Cptes1,6)) | F6: =IF(Cptes1="","",LEFT(Cptes1,7)) | G6: =IF(Cptes1="","",LEFT(Cptes1,7)) | H6: =IF(Cptes1="","",LEFT(Cptes1,7))
A7: =IF(Cptes1="","",LEFT(Cptes1,2)) | B7: =IF(Cptes1="","",LEFT(Cptes1,3)) | C7: =IF(Cptes1="","",LEFT(Cptes1,4)) | D7: =IF(Cptes1="","",LEFT(Cptes1,5)) | E7: =IF(Cptes1="","",LEFT(Cptes1,6)) | F7: =IF(Cptes1="","",LEFT(Cptes1,7)) | G7: =IF(Cptes1="","",LEFT(Cptes1,7)) | H7: =IF(Cptes1="","",LEFT(Cptes1,7))
A8: =IF(Cptes1="","",LEFT(Cptes1,2)) | B8: =IF(Cptes1="","",LEFT(Cptes1,3)) | C8: =IF(Cptes1="","",LEFT(Cptes1,4)) | D8: =IF(Cptes1="","",LEFT(Cptes1,5)) | E8: =IF(Cptes1="","",LEFT(Cptes1,6)) | F8: =IF(Cptes1="","",LEFT(Cptes1,7)) | G8: =IF(Cptes1="","",LEFT(Cptes1,7)) | H8: =IF(Cptes1="","",LEFT(Cptes1,7))
A9: =IF(Cptes1="","",LEFT(Cptes1,2)) | B9: =IF(Cptes1="","",LEFT(Cptes1,3)) | C9: =IF(Cptes1="","",LEFT(Cptes1,4)) | D9: =IF(Cptes1="","",LEFT(Cptes1,5)) | E9: =IF(Cptes1="","",LEFT(Cptes1,6)) | F9: =IF(Cptes1="","",LEFT(Cptes1,7)) | G9: =IF(Cptes1="","",LEFT(Cptes1,7)) | H9: =IF(Cptes1="","",LEFT(Cptes1,7))
A10: =IF(Cptes1="","",LEFT(Cptes1,2)) | B10: =IF(Cptes1="","",LEFT(Cptes1,3)) | C10: =IF(Cptes1="","",LEFT(Cptes1,4)) | D10: =IF(Cptes1="","",LEFT(Cptes1,5)) | E10: =IF(Cptes1="","",LEFT(Cptes1,6)) | F10: =IF(Cptes1="","",LEFT(Cptes1,7)) | G10: =IF(Cptes1="","",LEFT(Cptes1,7)) | H10: =IF(Cptes1="","",LEFT(Cptes1,7))
A11: =IF(Cptes1="","",LEFT(Cptes1,2)) | B11: =IF(Cptes1="","",LEFT(Cptes1,3)) | C11: =IF(Cptes1="","",LEFT(Cptes1,4)) | D11: =IF(Cptes1="","",LEFT(Cptes1,5)) | E11: =IF(Cptes1="","",LEFT(Cptes1,6)) | F11: =IF(Cptes1="","",LEFT(Cptes1,7)) | G11: =IF(Cptes1="","",LEFT(Cptes1,7)) | H11: =IF(Cptes1="","",LEFT(Cptes1,7))
A12: =IF(Cptes1="","",LEFT(Cptes1,2)) | B12: =IF(Cptes1="","",LEFT(Cptes1,3)) | C12: =IF(Cptes1="","",LEFT(Cptes1,4)) | D12: =IF(Cptes1="","",LEFT(Cptes1,5)) | E12: =IF(Cptes1="","",LEFT(Cptes1,6)) | F12: =IF(Cptes1="","",LEFT(Cptes1,7)) | G12: =IF(Cptes1="","",LEFT(Cptes1,7)) | H12: =IF(Cptes1="","",LEFT(Cptes1,7))
A13: =IF(Cptes1="","",LEFT(Cptes1,2)) | B13: =IF(Cptes1="","",LEFT(Cptes1,3)) | C13: =IF(Cptes1="","",LEFT(Cptes1,4)) | D13: =IF(Cptes1="","",LEFT(Cptes1,5)) | E13: =IF(Cptes1="","",LEFT(Cptes1,6)) | F13: =IF(Cptes1="","",LEFT(Cptes1,7)) | G13: =IF(Cptes1="","",LEFT(Cptes1,7)) | H13: =IF(Cptes1="","",LEFT(Cptes1,7))
A14: =IF(Cptes1="","",LEFT(Cptes1,2)) | B14: =IF(Cptes1="","",LEFT(Cptes1,3)) | C14: =IF(Cptes1="","",LEFT(Cptes1,4)) | D14: =IF(Cptes1="","",LEFT(Cptes1,5)) | E14: =IF(Cptes1="","",LEFT(Cptes1,6)) | F14: =IF(Cptes1="","",LEFT(Cptes1,7)) | G14: =IF(Cptes1="","",LEFT(Cptes1,7)) | H14: =IF(Cptes1="","",LEFT(Cptes1,7))
... A2201: =IF(Cptes1="","",LEFT(Cptes1,2)) | B2201: =IF(Cptes1="","",LEFT(Cptes1,3)) | C2201: =IF(Cptes1="","",LEFT(Cptes1,4)) | D2201: =IF(Cptes1="","",LEFT(Cptes1,5)) | E2201: =IF(Cptes1="","",LEFT(Cptes1,6)) | F2201: =IF(Cptes1="","",LEFT(Cptes1,7)) | G2201: =IF(Cptes1="","",LEFT(Cptes1,7)) | H2201: =IF(Cptes1="","",LEFT(Cptes1,7))

Sheet CONTROLE BALANCE
A1: EQUILIBRE DE LA BALANCE
A2: BALANCE N | B2: Solde Initial Débit | C2: Solde Initial Crédit | D2: Mouvements Débit | E2: Mouvements Crédit | F2: Solde Final Débit | G2: Solde Final Crédit
B3: =SUM(sid) -> 0 | C3: =SUM(sic) -> 0 | D3: =SUM(md) -> 0 | E3: =SUM(mc) -> 0 | F3: =SUM(sfd) -> 0 | G3: =SUM(sfc) -> 0
B4: =IF((B3-C3)>0,"Déséquilibre : Débit > de "&TEXT((B3-C3),"# ##0"),IF((B3-C3)<0,"Déséquilibre : Crédit > de "&-TEXT((B3-C3),"# ##0"),IF((B3-C3)=0,"Equilibre",0))) -> Equilibre | D4: =IF((D3-E3)>0,"Déséquilibre : Débit > de "&TEXT((D3-E3),"# ##0"),IF((D3-E3)<0,"Déséquilibre : Crédit > de "&-TEXT((D3-E3),"# ##0"),IF((D3-E3)=0,"Equilibre",0))) -> Equilibre | F4: =IF((F3-G3)>0,"Equilibre : Débit > de "&TEXT((F3-G3),"# ##0"),IF((F3-G3)<0,"Déséquilibre : Crédit > de "&-TEXT((F3-G3),"# ##0"),IF((F3-G3)=0,"Equilibre",0))) -> Equilibre
A5: BALANCE N-1 | B5: Solde Initial Débit | C5: Solde Initial Crédit | D5: Mouvements Débit | E5: Mouvements Crédit | F5: Solde Final Débit | G5: Solde Final Crédit
B6: =SUM(_sid1) -> 0 | C6: =SUM(_sic1) -> 0 | D6: =SUM(_md1) -> 0 | E6: =SUM(_mc1) -> 0 | F6: =SUM(_sfd1) -> 0 | G6: =SUM(_sfc1) -> 0
B7: =IF((B6-C6)>0,"Déséquilibre : Débit > de "&TEXT((B6-C6),"# ##0"),IF((B6-C6)<0,"Déséquilibre : Crédit > de "&-TEXT((B6-C6),"# ##0"),IF((B6-C6)=0,"Equilibre",0))) -> Equilibre | D7: =IF((D6-E6)>0,"Déséquilibre : Débit > de "&TEXT((D6-E6),"# ##0"),IF((D6-E6)<0,"Déséquilibre : Crédit > de "&-TEXT((D6-E6),"# ##0"),IF((D6-E6)=0,"Equilibre",0))) -> Equilibre | F7: =IF((F6-G6)>0,"Equilibre : Débit > de "&TEXT((F6-G6),"# ##0"),IF((F6-G6)<0,"Déséquilibre : Crédit > de "&-TEXT((F6-G6),"# ##0"),IF((F6-G6)=0,"Equilibre",0))) -> Equilibre

Sheet EQUILIBRE BALANCE N
A1: CPTE | B1: INTITULES DES COMPTES | C1: S.I. DEBIT | D1: S.I. CREDIT | E1: MOUV. DEBIT | F1: MOUV. CREDIT | G1: S.F. DEBIT | H1: S.F. CREDIT | I1: MONTANT DESEQUILIBRE
A2: ='Balance N'!I5 -> 0 | B2: ='Balance N'!J5 -> 0 | C2: ='Balance N'!K5 -> 0 | D2: ='Balance N'!L5 -> 0 | E2: ='Balance N'!M5 -> 0 | F2: ='Balance N'!N5 -> 0 | G2: ='Balance N'!O5 -> 0 | H2: ='Balance N'!P5 -> 0 | I2: =(C2-D2)+(E2-F2)-(G2-H2) -> 0
A3: ='Balance N'!I6 -> 0 | B3: ='Balance N'!J6 -> 0 | C3: ='Balance N'!K6 -> 0 | D3: ='Balance N'!L6 -> 0 | E3: ='Balance N'!M6 -> 0 | F3: ='Balance N'!N6 -> 0 | G3: ='Balance N'!O6 -> 0 | H3: ='Balance N'!P6 -> 0 | I3: =(C3-D3)+(E3-F3)-(G3-H3) -> 0
A4: ='Balance N'!I7 -> 0 | B4: ='Balance N'!J7 -> 0 | C4: ='Balance N'!K7 -> 0 | D4: ='Balance N'!L7 -> 0 | E4: ='Balance N'!M7 -> 0 | F4: ='Balance N'!N7 -> 0 | G4: ='Balance N'!O7 -> 0 | H4: ='Balance N'!P7 -> 0 | I4: =(C4-D4)+(E4-F4)-(G4-H4) -> 0
A5: ='Balance N'!I8 -> 0 | B5: ='Balance N'!J8 -> 0 | C5: ='Balance N'!K8 -> 0 | D5: ='Balance N'!L8 -> 0 | E5: ='Balance N'!M8 -> 0 | F5: ='Balance N'!N8 -> 0 | G5: ='Balance N'!O8 -> 0 | H5: ='Balance N'!P8 -> 0 | I5: =(C5-D5)+(E5-F5)-(G5-H5) -> 0
A6: ='Balance N'!I9 -> 0 | B6: ='Balance N'!J9 -> 0 | C6: ='Balance N'!K9 -> 0 | D6: ='Balance N'!L9 -> 0 | E6: ='Balance N'!M9 -> 0 | F6: ='Balance N'!N9 -> 0 | G6: ='Balance N'!O9 -> 0 | H6: ='Balance N'!P9 -> 0 | I6: =(C6-D6)+(E6-F6)-(G6-H6) -> 0
A7: ='Balance N'!I10 -> 0 | B7: ='Balance N'!J10 -> 0 | C7: ='Balance N'!K10 -> 0 | D7: ='Balance N'!L10 -> 0 | E7: ='Balance N'!M10 -> 0 | F7: ='Balance N'!N10 -> 0 | G7: ='Balance N'!O10 -> 0 | H7: ='Balance N'!P10 -> 0 | I7: =(C7-D7)+(E7-F7)-(G7-H7) -> 0
A8: ='Balance N'!I11 -> 0 | B8: ='Balance N'!J11 -> 0 | C8: ='Balance N'!K11 -> 0 | D8: ='Balance N'!L11 -> 0 | E8: ='Balance N'!M11 -> 0 | F8: ='Balance N'!N11 -> 0 | G8: ='Balance N'!O11 -> 0 | H8: ='Balance N'!P11 -> 0 | I8: =(C8-D8)+(E8-F8)-(G8-H8) -> 0
A9: ='Balance N'!I12 -> 0 | B9: ='Balance N'!J12 -> 0 | C9: ='Balance N'!K12 -> 0 | D9: ='Balance N'!L12 -> 0 | E9: ='Balance N'!M12 -> 0 | F9: ='Balance N'!N12 -> 0 | G9: ='Balance N'!O12 -> 0 | H9: ='Balance N'!P12 -> 0 | I9: =(C9-D9)+(E9-F9)-(G9-H9) -> 0
A10: ='Balance N'!I13 -> 0 | B10: ='Balance N'!J13 -> 0 | C10: ='Balance N'!K13 -> 0 | D10: ='Balance N'!L13 -> 0 | E10: ='Balance N'!M13 -> 0 | F10: ='Balance N'!N13 -> 0 | G10: ='Balance N'!O13 -> 0 | H10: ='Balance N'!P13 -> 0 | I10: =(C10-D10)+(E10-F10)-(G10-H10) -> 0
A11: ='Balance N'!I14 -> 0 | B11: ='Balance N'!J14 -> 0 | C11: ='Balance N'!K14 -> 0 | D11: ='Balance N'!L14 -> 0 | E11: ='Balance N'!M14 -> 0 | F11: ='Balance N'!N14 -> 0 | G11: ='Balance N'!O14 -> 0 | H11: ='Balance N'!P14 -> 0 | I11: =(C11-D11)+(E11-F11)-(G11-H11) -> 0
A12: ='Balance N'!I15 -> 0 | B12: ='Balance N'!J15 -> 0 | C12: ='Balance N'!K15 -> 0 | D12: ='Balance N'!L15 -> 0 | E12: ='Balance N'!M15 -> 0 | F12: ='Balance N'!N15 -> 0 | G12: ='Balance N'!O15 -> 0 | H12: ='Balance N'!P15 -> 0 | I12: =(C12-D12)+(E12-F12)-(G12-H12) -> 0
A13: ='Balance N'!I16 -> 0 | B13: ='Balance N'!J16 -> 0 | C13: ='Balance N'!K16 -> 0 | D13: ='Balance N'!L16 -> 0 | E13: ='Balance N'!M16 -> 0 | F13: ='Balance N'!N16 -> 0 | G13: ='Balance N'!O16 -> 0 | H13: ='Balance N'!P16 -> 0 | I13: =(C13-D13)+(E13-F13)-(G13-H13) -> 0
... A7689: ='Balance N'!I7692 -> 0 | B7689: ='Balance N'!J7692 -> 0 | C7689: ='Balance N'!K7692 -> 0 | D7689: ='Balance N'!L7692 -> 0 | E7689: ='Balance N'!M7692 -> 0 | F7689: ='Balance N'!N7692 -> 0 | G7689: ='Balance N'!O7692 -> 0 | H7689: ='Balance N'!P7692 -> 0 | I7689: =(C7689-D7689)+(E7689-F7689)-(G7689-H7689) -> 0

Sheet EQUILIBRE BALANCE N-1
A1: CPTE | B1: INTITULES DES COMPTES | C1: S.I. DEBIT | D1: S.I. CREDIT | E1: MOUV. DEBIT | F1: MOUV. CREDIT | G1: S.F. DEBIT | H1: S.F. CREDIT | I1: MONTANT DESEQUILIBRE
A2: ='Balance N-1'!I5 -> 0 | B2: ='Balance N-1'!J5 -> 0 | C2: ='Balance N-1'!K5 -> 0 | D2: ='Balance N-1'!L5 -> 0 | E2: ='Balance N-1'!M5 -> 0 | F2: ='Balance N-1'!N5 -> 0 | G2: ='Balance N-1'!O5 -> 0 | H2: ='Balance N-1'!P5 -> 0 | I2: =(C2-D2)+(E2-F2)-(G2-H2) -> 0
A3: ='Balance N-1'!I6 -> 0 | B3: ='Balance N-1'!J6 -> 0 | C3: ='Balance N-1'!K6 -> 0 | D3: ='Balance N-1'!L6 -> 0 | E3: ='Balance N-1'!M6 -> 0 | F3: ='Balance N-1'!N6 -> 0 | G3: ='Balance N-1'!O6 -> 0 | H3: ='Balance N-1'!P6 -> 0 | I3: =(C3-D3)+(E3-F3)-(G3-H3) -> 0
A4: ='Balance N-1'!I7 -> 0 | B4: ='Balance N-1'!J7 -> 0 | C4: ='Balance N-1'!K7 -> 0 | D4: ='Balance N-1'!L7 -> 0 | E4: ='Balance N-1'!M7 -> 0 | F4: ='Balance N-1'!N7 -> 0 | G4: ='Balance N-1'!O7 -> 0 | H4: ='Balance N-1'!P7 -> 0 | I4: =(C4-D4)+(E4-F4)-(G4-H4) -> 0
A5: ='Balance N-1'!I8 -> 0 | B5: ='Balance N-1'!J8 -> 0 | C5: ='Balance N-1'!K8 -> 0 | D5: ='Balance N-1'!L8 -> 0 | E5: ='Balance N-1'!M8 -> 0 | F5: ='Balance N-1'!N8 -> 0 | G5: ='Balance N-1'!O8 -> 0 | H5: ='Balance N-1'!P8 -> 0 | I5: =(C5-D5)+(E5-F5)-(G5-H5) -> 0
A6: ='Balance N-1'!I9 -> 0 | B6: ='Balance N-1'!J9 -> 0 | C6: ='Balance N-1'!K9 -> 0 | D6: ='Balance N-1'!L9 -> 0 | E6: ='Balance N-1'!M9 -> 0 | F6: ='Balance N-1'!N9 -> 0 | G6: ='Balance N-1'!O9 -> 0 | H6: ='Balance N-1'!P9 -> 0 | I6: =(C6-D6)+(E6-F6)-(G6-H6) -> 0
A7: ='Balance N-1'!I10 -> 0 | B7: ='Balance N-1'!J10 -> 0 | C7: ='Balance N-1'!K10 -> 0 | D7: ='Balance N-1'!L10 -> 0 | E7: ='Balance N-1'!M10 -> 0 | F7: ='Balance N-1'!N10 -> 0 | G7: ='Balance N-1'!O10 -> 0 | H7: ='Balance N-1'!P10 -> 0 | I7: =(C7-D7)+(E7-F7)-(G7-H7) -> 0
A8: ='Balance N-1'!I11 -> 0 | B8: ='Balance N-1'!J11 -> 0 | C8: ='Balance N-1'!K11 -> 0 | D8: ='Balance N-1'!L11 -> 0 | E8: ='Balance N-1'!M11 -> 0 | F8: ='Balance N-1'!N11 -> 0 | G8: ='Balance N-1'!O11 -> 0 | H8: ='Balance N-1'!P11 -> 0 | I8: =(C8-D8)+(E8-F8)-(G8-H8) -> 0
A9: ='Balance N-1'!I12 -> 0 | B9: ='Balance N-1'!J12 -> 0 | C9: ='Balance N-1'!K12 -> 0 | D9: ='Balance N-1'!L12 -> 0 | E9: ='Balance N-1'!M12 -> 0 | F9: ='Balance N-1'!N12 -> 0 | G9: ='Balance N-1'!O12 -> 0 | H9: ='Balance N-1'!P12 -> 0 | I9: =(C9-D9)+(E9-F9)-(G9-H9) -> 0
A10: ='Balance N-1'!I13 -> 0 | B10: ='Balance N-1'!J13 -> 0 | C10: ='Balance N-1'!K13 -> 0 | D10: ='Balance N-1'!L13 -> 0 | E10: ='Balance N-1'!M13 -> 0 | F10: ='Balance N-1'!N13 -> 0 | G10: ='Balance N-1'!O13 -> 0 | H10: ='Balance N-1'!P13 -> 0 | I10: =(C10-D10)+(E10-F10)-(G10-H10) -> 0
A11: ='Balance N-1'!I14 -> 0 | B11: ='Balance N-1'!J14 -> 0 | C11: ='Balance N-1'!K14 -> 0 | D11: ='Balance N-1'!L14 -> 0 | E11: ='Balance N-1'!M14 -> 0 | F11: ='Balance N-1'!N14 -> 0 | G11: ='Balance N-1'!O14 -> 0 | H11: ='Balance N-1'!P14 -> 0 | I11: =(C11-D11)+(E11-F11)-(G11-H11) -> 0
A12: ='Balance N-1'!I15 -> 0 | B12: ='Balance N-1'!J15 -> 0 | C12: ='Balance N-1'!K15 -> 0 | D12: ='Balance N-1'!L15 -> 0 | E12: ='Balance N-1'!M15 -> 0 | F12: ='Balance N-1'!N15 -> 0 | G12: ='Balance N-1'!O15 -> 0 | H12: ='Balance N-1'!P15 -> 0 | I12: =(C12-D12)+(E12-F12)-(G12-H12) -> 0
A13: ='Balance N-1'!I16 -> 0 | B13: ='Balance N-1'!J16 -> 0 | C13: ='Balance N-1'!K16 -> 0 | D13: ='Balance N-1'!L16 -> 0 | E13: ='Balance N-1'!M16 -> 0 | F13: ='Balance N-1'!N16 -> 0 | G13: ='Balance N-1'!O16 -> 0 | H13: ='Balance N-1'!P16 -> 0 | I13: =(C13-D13)+(E13-F13)-(G13-H13) -> 0
... A7689: ='Balance N-1'!I7692 -> 0 | B7689: ='Balance N-1'!J7692 -> 0 | C7689: ='Balance N-1'!K7692 -> 0 | D7689: ='Balance N-1'!L7692 -> 0 | E7689: ='Balance N-1'!M7692 -> 0 | F7689: ='Balance N-1'!N7692 -> 0 | G7689: ='Balance N-1'!O7692 -> 0 | H7689: ='Balance N-1'!P7692 -> 0 | I7689: =(C7689-D7689)+(E7689-F7689)-(G7689-H7689) -> 0

Sheet COUVERTURE
F4: REPUBLIQUE DE……..
C6: MINISTERE DE L'ECONOMIE DES FINANCES ET DU DEVELOPPEMENT
F8: DIRECTION GENERALE DES IMPOTS
E31: LIASSE SYSTEME NORMAL

Sheet GARDE
B2: BURKINA FASO
B3: MINISTERE DE L'ECONOMIE DES FINANCES ET DU DEVELOPPEMENT
B4: DIRECTION GENERALE DES IMPOTS
C8: CENTRE DE DEPOT DE
D9: =+'INFORMATIONS GENERALES'!E11 -> 0
B12: ETATS FINANCIERS NORMALISES DU SYSTEME COMPTABLE DES ENTITES A BUT NON LUCRATIF (SYCEBNL)
B15: Projets de développement et assimilés
E17: EXERCICE CLOS LE
E18: =+'INFORMATIONS GENERALES'!J13 -> 45657
D21: DESIGNATION DE L'ENTITE
B23: DENOMINATION SOCIALE : | D23: =+'INFORMATIONS GENERALES'!E21 -> DSO Services
B24: (ou nom et prénoms de l'exploitant)
B27: SIGLE USUEL : | C27: =+'INFORMATIONS GENERALES'!L21 -> DSO Services
B29: ADRESSE COMPLETE : | C29: =+'INFORMATIONS GENERALES'!E28 -> Rue Alphamoi Djénèpo, secteur 01, Bobo-Dioulasso, Burkina Faso
B31: N° IFU DU CONTRIBUABLE : | D31: =+'INFORMATIONS GENERALES'!P53 -> 00000101A
B32: N° DE TELEDECLARANT (NES): | D32: =+'INFORMATIONS GENERALES'!P56 -> Néant
B33: SYSTEME NORMAL
B34: Documents déposés | H34: Réservé à la Direction Générale des Impôts
B36: Fiche d'identification et renseignements divers | H36: Date de dépôt
B37: Bilan
B38: Compte de résultat
B39: Tableau des flux de trésorerie
B40: Notes annexes | H40: Nom de l'agent de la DGI ayant réceptionné le dépôt
B41: Etats supplémentaires DGI
B45: Nombre de pages déposées par exemplaire : | H45: Signature de l'agent et cachet du service
B46: Nombre d'exemplaires déposés :

Sheet FICHE R1
A1: - 1 -
R2: FICHE R1
A3: Dénomination sociale de l'entité : | E3: =+'INFORMATIONS GENERALES'!E21 -> DSO Services
A4: Adresse : | D4: =+'INFORMATIONS GENERALES'!E28 -> Rue Alphamoi Djénèpo, secteur 01, Bobo-Dioulasso, Burkina Faso | P4: Sigle usuel : | S4: =+'INFORMATIONS GENERALES'!L21 -> DSO Services
A5: N° IFU du contribuable : | E5: =+'INFORMATIONS GENERALES'!P53 -> 00000101A | H5: Exercice clos le : | J5: =+'INFORMATIONS GENERALES'!J13 -> 45657 | Q5: Durée (en mois) : | U5: =+'INFORMATIONS GENERALES'!W13 -> 12
A6: N° de télédéclarant (NES) : | E6: =+'INFORMATIONS GENERALES'!P56 -> Néant
A7: FICHE R1 : FICHE D'IDENTIFICATION ET RENSEIGNEMENTS DIVERS 1
A8: ZA | C8: EXERCICE COMPTABLE : | M8: DU: | N8: =+'INFORMATIONS GENERALES'!P9 -> 45292 | R8: AU: | S8: =+'INFORMATIONS GENERALES'!U9 -> 45657
A10: ZB | C10: DATE D'ARRETE EFFECTIF DES COMPTES : | H10: =+'INFORMATIONS GENERALES'!J11 -> 45747 | T10: ZD
A12: ZC | C12: EXERCICE PRECEDENT CLOS LE : | H12: =+'INFORMATIONS GENERALES'!J13 -> 45657 | K12: DUREE EXERCICE PRECEDENT EN MOIS : | U12: =+'INFORMATIONS GENERALES'!W13 -> 12
A14: ZE | C14: =+'INFORMATIONS GENERALES'!E15 -> 10 | D14: =+'INFORMATIONS GENERALES'!F15 -> 0 | J14: ZF | K14: ='INFORMATIONS GENERALES'!M15 -> 0
C15: Greffe | D15: N°Registre du Commerce | K15: N° Répertoire des entités
A17: ZG | C17: =+'INFORMATIONS GENERALES'!E18 -> 0 | E17: ZH | F17: =+'INFORMATIONS GENERALES'!H18 -> 0 | P17: ZI | Q17: =+'INFORMATIONS GENERALES'!S18 -> A0101
C18: N° de caisse sociale | F18: N° Code Importateur | Q18: Code activité principale
A20: ZJ | C20: =+'INFORMATIONS GENERALES'!E21 -> DSO Services | Q20: =+'INFORMATIONS GENERALES'!L21 -> DSO Services
C21: Désignation de l'entité | Q21: Sigle
A23: ZK | C23: ='INFORMATIONS GENERALES'!E24 -> 76191918 | E23: =+'INFORMATIONS GENERALES'!G24 -> scheckoumard@gmail.com | K23: =+'INFORMATIONS GENERALES'!K24 -> 01 | N23: =+'INFORMATIONS GENERALES'!L24 -> 13 | Q23: =+'INFORMATIONS GENERALES'!N24 -> Bobo-Dioulasso
C24: N° de téléphone | E24: Adresse e-mail | K24: Code | N24: Boîte Postale | Q24: Ville
A26: ZL | C26: =+'INFORMATIONS GENERALES'!E28 -> Rue Alphamoi Djénèpo, secteur 01, Bobo-Dioulasso, Burkina Faso
C27: Adresse géographique complète (Immeuble, rue, quartier, ville, pays)
P28: ZN
A29: ZM | C29: =+'INFORMATIONS GENERALES'!E31 -> 0 | P29: =+'INFORMATIONS GENERALES'!R31 -> 1
C30: Désignation précise de l'activité principale exercée par l'entité | P30: % Capacité production utile
A32: ZO
C33: Nom, adresse, téléphone, adresse e-mail et qualité de la personne à contacter en cas de demande
A35: ZP
C36: Nom, adresse, téléphone et e-mail du salarié de l'entité ou
C37: du professionnel comptable inscrit à l'Ordre des Experts-comptables ayant établi les états financiers
A39: ZQ
A43: ZR
C44: Nom, adresse, téléphone, e-mail et numéro d'inscription à l'Ordre des Experts-comptables
C45: de l'Expert comptablble ayant délivré l'attestation d'exécution de la mission du commissariat aux comptes
A47: ZS | O47: Non | T47: Oui
N48: Etats financiers approuvés par l'Assemblée Générale (cocher la case)
J49: ZW
A50: ZT | J50: Domiciliations bancaires
C51: Nom du signataire des états financiers | J51: Banque | Q51: Numéro de compte
A53: ZU
C54: Qualité du signataire des états financiers
A56: ZV
...

Sheet FICHE R2
A1: - 2 -
AG2: FICHE R2
A3: Dénomination sociale de l'entité : | I3: =+GARDE!D23 -> DSO Services
A4: Adresse : | E4: =+GARDE!C29 -> Rue Alphamoi Djénèpo, secteur 01, Bobo-Dioulasso, Burkina Faso | AC4: Sigle usuel : | AI4: =+GARDE!C27 -> DSO Services
A5: N° IFU du contribuable : | I5: =+GARDE!D31 -> 00000101A | Q5: Exercice clos le : | W5: =+GARDE!E18 -> 45657 | AC5: Durée (en mois) : | AI5: =+'FICHE R1'!U5 -> 12
A6: N° de télédéclarant (NES) : | I6: =+GARDE!D32 -> Néant
A7: FICHE D'IDENTIFICATION ET RENSEIGNEMENTS DIVERS
A8: EQUIPE DE L'ENTITE A BUT NON LUCRATIF
A9: Nom et Prénoms | I9: Nationalité | P9: Autre nationalité (à préciser) | V9: Qualité | AB9: N° d'identification fiscale | AG9: Adresse (BP, ville, pays, adresse géographique et adresse email)

Sheet TER
A1: - 5 -
G2: TABLEAU EMPLOIS - RESSOURCES PAGE 1/1
A3: Dénomination sociale : | C3: =+'FICHE R2'!I3 -> DSO Services
A4: Adresse : | C4: =+'FICHE R2'!E4 -> Rue Alphamoi Djénèpo, secteur 01, Bobo-Dioulasso, Burkina Faso | G4: Sigle usuel : | H4: =+'FICHE R2'!AI4 -> DSO Services
A5: N° IFU du contribuable : | C5: =+'FICHE R2'!I5 -> 00000101A | E5: Exercice clos le : | F5: =+'FICHE R2'!W5 -> 45657 | G5: Durée (en mois) : | H5: =+'FICHE R2'!AI5 -> 12
A6: N° de télédéclarant (NES) : | C6: =+'FICHE R2'!I6 -> Néant
A7: TABLEAU EMPLOIS RESSOURCES
A8: =CONCATENATE("TABLEAU EMPLOIS - RESSOURCES AU 31/12/"&" "&TEXT('INFORMATIONS GENERALES'!J13,"aaaa")) -> TABLEAU EMPLOIS - RESSOURCES AU 31/12/ 2024
A9: REF | B9: DESIGNATION | F9: SOLDE CUMULE DEBUT EXERCICE N | G9: EXERCICE N | H9: SOLDE CUMULE FIN EXERCICE N
A10: FA | B10: Fonds reçus, Bailleurs | F10: =SUMIF('Balance N'!B:B,161,'Balance N'!L:L)+SUMIF('Balance N'!B:B,162,'Balance N'!L:L)+SUMIF('Balance N'!B:B,462,'Balance N'!L:L) -> 0 | G10: =SUMIF('Balance N'!B:B,161,'Balance N'!N:N)+SUMIF('Balance N'!B:B,162,'Balance N'!N:N)+SUMIF('Balance N'!B:B,462,'Balance N'!N:N) -> 0 | H10: =+F10+G10 -> 0
A11: FB | B11: Fonds reçus, Bailleurs | F11: 0 | G11: 0 | H11: =+F11+G11 -> 0
A12: FC | B12: Fonds contrepartie État | F12: =SUMIF('Balance N'!B:B,163,'Balance N'!L:L)+SUMIF('Balance N'!B:B,463,'Balance N'!L:L) -> 0 | G12: =SUMIF('Balance N'!B:B,163,'Balance N'!N:N)+SUMIF('Balance N'!B:B,463,'Balance N'!N:N) -> 0 | H12: =+F12+G12 -> 0
A13: FD | B13: Autres fonds reçus | F13: =SUMIF('Balance N'!B:B,164,'Balance N'!L:L)+SUMIF('Balance N'!B:B,464,'Balance N'!L:L)+SUMIF('Balance N'!B:B,707,'Balance N'!L:L)+SUMIF('Balance N'!A:A,77,'Balance N'!L:L) -> 0 | G13: =SUMIF('Balance N'!B:B,164,'Balance N'!N:N)+SUMIF('Balance N'!B:B,464,'Balance N'!N:N)+SUMIF('Balance N'!B:B,707,'Balance N'!N:N)+SUMIF('Balance N'!A:A,77,'Balance N'!N:N) -> 0 | H13: =+F13+G13 -> 0
A14: GR | B14: I.RESSOURCES | F14: =SUM(F10:F13) -> 0 | G14: =SUM(G10:G13) -> 0 | H14: =SUM(H10:H13) -> 0
A15: FE | B15: Immobilisations incorporelle | F15: =SUMIF('Balance N'!A:A,21,'Balance N'!K:K) -> 0 | G15: =SUMIF('Balance N'!A:A,21,'Balance N'!M:M)-(SUMIF('Balance N-1'!C:C,4811,'Balance N-1'!P:P)-SUMIF('Balance N'!C:C,4811,'Balance N'!P:P))-SUMIF('Balance N'!C:C,4813,'Balance N'!P:P) -> 0 | H15: =+F15+G15 -> 0
A16: FF | B16: Terrains | F16: =SUMIF('Balance N'!A:A,22,'Balance N'!K:K) -> 0 | G16: =SUMIF('Balance N'!A:A,22,'Balance N'!M:M)-(SUMIF('Balance N-1'!C:C,4812,'Balance N-1'!P:P)-SUMIF('Balance N'!C:C,4812,'Balance N'!P:P))-SUMIF('Balance N'!C:C,4813,'Balance N'!P:P) -> 0 | H16: =+F16+G16 -> 0
A17: FG | B17: Bâtiments | F17: =SUMIF('Balance N-1'!B:B,231,'Balance N-1'!K:K)+SUMIF('Balance N'!B:B,232,'Balance N'!K:K)+SUMIF('Balance N'!B:B,233,'Balance N'!K:K)+SUMIF('Balance N'!C:C,2391,'Balance N'!K:K)+SUMIF('Balance N'!C:C,2392,'Balance N'!K:K)+SUMIF('Balance N'!C:C,2393,'Balance N'!K:K)+SUMIF('Balance N'!C:C,2396,'Balance N'!K:K) -> 0 | G17: =SUMIF('Balance N'!B:B,231,'Balance N'!M:M)+SUMIF('Balance N'!B:B,232,'Balance N'!M:M)+SUMIF('Balance N'!B:B,233,'Balance N'!M:M)+SUMIF('Balance N'!C:C,2391,'Balance N'!M:M)+SUMIF('Balance N'!C:C,2392,'Balance N'!M:M)+SUMIF('Balance N'!C:C,2393,'Balance N'!M:M)+SUMIF('Balance N'!C:C,2396,'Balance N'!M:M)-(SUMIF('Balance N-1'!C:C,4812,'Balance N-1'!P:P)-SUMIF('Balance N'!C:C,4812,'Balance N'!P:P))-SUMIF('Balance N'!C:C,4813,'Balance N'!P:P) -> 0 | H17: =+F17+G17 -> 0
A18: FH | B18: Aménagements, agencements et installations | F18: =SUMIF('Balance N-1'!B:B,234,'Balance N-1'!K:K)+SUMIF('Balance N'!B:B,235,'Balance N'!K:K)+SUMIF('Balance N'!B:B,238,'Balance N'!K:K)+SUMIF('Balance N'!C:C,2394,'Balance N'!K:K)+SUMIF('Balance N'!C:C,2395,'Balance N'!K:K)+SUMIF('Balance N'!C:C,2398,'Balance N'!K:K) -> 0 | G18: =SUMIF('Balance N'!B:B,234,'Balance N'!M:M)+SUMIF('Balance N'!B:B,235,'Balance N'!M:M)+SUMIF('Balance N'!B:B,238,'Balance N'!M:M)+SUMIF('Balance N'!C:C,2394,'Balance N'!M:M)+SUMIF('Balance N'!C:C,2395,'Balance N'!M:M)+SUMIF('Balance N'!C:C,2398,'Balance N'!M:M)-(SUMIF('Balance N-1'!C:C,4812,'Balance N-1'!P:P)-SUMIF('Balance N'!C:C,4812,'Balance N'!P:P))-SUMIF('Balance N'!C:C,4813,'Balance N'!P:P) -> 0 | H18: =+F18+G18 -> 0
A19: FI | B19: Matériel, mobilier et actifs biologiques | F19: =SUMIF('Balance N'!A:A,24,'Balance N'!K:K) -> 0 | G19: =SUMIF('Balance N'!A:A,24,'Balance N'!M:M)-(SUMIF('Balance N-1'!C:C,4812,'Balance N-1'!P:P)-SUMIF('Balance N'!C:C,4812,'Balance N'!P:P))-SUMIF('Balance N'!C:C,4813,'Balance N'!P:P)-SUMIF('Balance N'!B:B,245,'Balance N'!M:M)-SUMIF('Balance N'!C:C,2495,'Balance N'!M:M) -> 0 | H19: =+F19+G19 -> 0
A20: FJ | B20: Matériel de transport | F20: =SUMIF('Balance N'!B:B,245,'Balance N'!K:K)+SUMIF('Balance N'!C:C,2495,'Balance N'!K:K) -> 0 | G20: =SUMIF('Balance N'!B:B,245,'Balance N'!M:M)+SUMIF('Balance N'!C:C,2495,'Balance N'!M:M)-(SUMIF('Balance N-1'!C:C,4812,'Balance N-1'!P:P)-SUMIF('Balance N'!C:C,4812,'Balance N'!P:P)) -> 0 | H20: =+F20+G20 -> 0
A21: FK | B21: Avances et acomptes sur immobilisations | F21: =SUMIF('Balance N'!A:A,25,'Balance N'!K:K) -> 0 | G21: =SUMIF('Balance N'!A:A,25,'Balance N'!M:M) -> 0 | H21: =+F21+G21 -> 0
A22: FL | B22: Immobilisation financières | F22: =SUMIF('Balance N'!A:A,26,'Balance N'!K:K)+SUMIF('Balance N'!A:A,27,'Balance N'!K:K) -> 0 | G22: =SUMIF('Balance N'!A:A,26,'Balance N'!M:M)+SUMIF('Balance N'!A:A,27,'Balance N'!M:M)-(SUMIF('Balance N-1'!C:C,4813,'Balance N-1'!O:O)-SUMIF('Balance N'!C:C,4813,'Balance N-1'!O:O))-SUMIF('Balance N-1'!B:B,276,'Balance N-1'!M:M) -> 0 | H22: =+F22+G22 -> 0
A23: GS | B23: A-TOTAL DES IMMOBILISATION | F23: =SUM(F15:F22) -> 0 | G23: =SUM(G15:G22) -> 0 | H23: =SUM(H15:H22) -> 0
A24: FM | B24: Achats de biens et services | F24: =SUMIF('Balance N'!A:A,60,'Balance N'!K:K) -> 0 | G24: =SUMIF('Balance N'!A:A,60,'Balance N'!M:M)-(SUMIF('Balance N-1'!B:B,4011,'Balance N'!O:O)-SUMIF('Balance N'!B:B,4011,'Balance N'!O:O))-(SUMIF('Balance N-1'!B:B,603,'Balance N'!O:O)-SUMIF('Balance N'!B:B,603,'Balance N'!P:P)) -> 0 | H24: =+F24+G24 -> 0
A25: FN | B25: Transport | F25: =SUMIF('Balance N'!A:A,61,'Balance N'!K:K) -> 0 | G25: =SUMIF('Balance N'!A:A,61,'Balance N'!M:M)-(SUMIF('Balance N-1'!C:C,4011,'Balance N'!O:O)-SUMIF('Balance N'!C:C,4011,'Balance N'!O:O)) -> 0 | H25: =+F25+G25 -> 0
A26: FO | B26: Services extérieurs | F26: =SUMIF('Balance N'!A:A,62,'Balance N'!K:K)+SUMIF('Balance N'!A:A,63,'Balance N'!K:K) -> 0 | G26: =SUMIF('Balance N'!A:A,62,'Balance N'!M:M)+SUMIF('Balance N'!A:A,63,'Balance N'!M:M)-(SUMIF('Balance N-1'!C:C,4013,'Balance N'!O:O)-SUMIF('Balance N'!C:C,4013,'Balance N'!O:O)) -> 0 | H26: =+F26+G26 -> 0
A27: FP | B27: Impôts et taxes | F27: =SUMIF('Balance N'!A:A,64,'Balance N'!K:K) -> 0 | G27: =SUMIF('Balance N'!A:A,64,'Balance N'!M:M)-(SUMIF('Balance N-1'!A:A,44,'Balance N'!O:O)-SUMIF('Balance N'!A:A,44,'Balance N'!O:O)) -> 0 | H27: =+F27+G27 -> 0
A28: FQ | B28: Autres charges | F28: =SUMIF('Balance N'!A:A,65,'Balance N'!K:K) -> 0 | G28: =SUMIF('Balance N'!A:A,65,'Balance N'!M:M)-(SUMIF('Balance N-1'!B:B,416,'Balance N'!O:O)-SUMIF('Balance N'!B:B,416,'Balance N'!O:O))-SUMIF('Balance N'!B:B,499,'Balance N'!O:O) -> 0 | H28: =+F28+G28 -> 0
A29: FR | B29: Charges de personnel | F29: =SUMIF('Balance N'!A:A,66,'Balance N'!K:K) -> 0 | G29: =SUMIF('Balance N'!A:A,66,'Balance N'!M:M)-(SUMIF('Balance N-1'!A:A,42,'Balance N'!O:O)-SUMIF('Balance N'!A:A,42,'Balance N'!O:O))-(SUMIF('Balance N-1'!A:A,43,'Balance N'!O:O)-SUMIF('Balance N'!A:A,43,'Balance N'!O:O)) -> 0 | H29: =+F29+G29 -> 0
A30: FS | B30: Charges financières | F30: =SUMIF('Balance N'!A:A,67,'Balance N'!K:K) -> 0 | G30: =SUMIF('Balance N'!A:A,67,'Balance N'!M:M)-SUMIF('Balance N'!B:B,166,'Balance N'!N:N) -> 0 | H30: =+F30+G30 -> 0
A31: FT | B31: Avances sur charges (à justifier) | F31: =SUMIF('Balance N'!C:C,4091,'Balance N'!K:K)+SUMIF('Balance N'!C:C,4093,'Balance N'!K:K) -> 0 | G31: =SUMIF('Balance N'!C:C,4091,'Balance N'!O:O)+SUMIF('Balance N'!C:C,4093,'Balance N'!O:O) -> 0 | H31: =+F31+G31 -> 0
A32: GT | B32: B-TOTAL DES CHARGES DE FONCTIONNEMENT | F32: =SUM(F24:F31) -> 0 | G32: =SUM(G24:G31) -> 0 | H32: =SUM(H24:H31) -> 0
A33: GU | B33: II.EMPLOIS (A+B) | F33: =+F23+F32 -> 0 | G33: =+G23+G32 -> 0 | H33: =+H23+H32 -> 0
A34: GV | B34: III.EXEDENT/DEFICIT DES FONDS RECUS SUR LES EMPLOIS (I-II) | F34: =+F14-F33 -> 0 | G34: =+G14-G33 -> 0 | H34: =+H14-H33 -> 0
A35: FU | B35: Fonds bailleur en début exercice N | F35: 0 | G35: =SUMIF('Balance N-1'!A:A,162,'Balance N-1'!O:O) -> 0 | H35: =+F35+G35 -> 0
A36: FV | B36: Fonds de contrepartie État en début exercice N | F36: 0 | G36: =SUMIF('Balance N-1'!A:A,163,'Balance N-1'!O:O) -> 0 | H36: =+F36+G36 -> 0
A37: FW | B37: Autres fons en début exercice N | F37: 0 | G37: =SUMIF('Balance N-1'!A:A,164,'Balance N-1'!O:O)+SUMIF('Balance N-1'!A:A,165,'Balance N-1'!O:O)+SUMIF('Balance N-1'!A:A,167,'Balance N-1'!O:O)+SUMIF('Balance N-1'!A:A,168,'Balance N-1'!O:O) -> 0 | H37: =+F37+G37 -> 0
A38: GW | B38: IV.FONDS DISPONIBLE EN DEBUT EXERCICE | F38: =SUM(F35:F37) -> 0 | G38: =SUM(G35:G37) -> 0 | H38: =SUM(H35:H37) -> 0
A39: GX | B39: V.MONTANT NET DE L'ENCAISSE DISPONIBLE (III+IV) | F39: =+F34+F38 -> 0 | G39: =+G34+G38 -> 0 | H39: =+H34+H38 -> 0
A40: FX | B40: Fonds bailleur en fin d'exercice N | F40: 0 | G40: =SUMIF('Balance N'!A:A,162,'Balance N'!O:O) -> 0 | H40: =+F40+G40 -> 0
...

Sheet TRC
A1: - 6 -
F2: TABLEAU RECONCILIATION TRESO PAGE 1/1
A3: Dénomination sociale : | B3: =+TER!C3 -> DSO Services
A4: Adresse : | B4: =+TER!C4 -> Rue Alphamoi Djénèpo, secteur 01, Bobo-Dioulasso, Burkina Faso | E4: Sigle usuel : | G4: =+TER!H4 -> DSO Services
A5: N° IFU du contribuable : | B5: =+TER!C5 -> 00000101A | C5: Exercice clos le : | D5: =+TER!F5 -> 45657 | E5: Durée (en mois) : | G5: =+TER!H5 -> 12
A6: N° de télédéclarant (NES) : | B6: =+TER!C6 -> Néant
A7: TABLEAU DE RECONCILIATION DE TRESORERIE
A8: TABLEAU DE RECONCILIATION DE LA TRESORERIE DU 01/01202N AU 31/121/202N
A9: LIBELLE | G9: MONTANT
A11: TRESORERIE EN DEBUT EXERCICE N | F11: A
A14: FONDS RECUS DES BAILLEURS AU COURS DE L'EXERCICE N | F14: B
A17: INTERETS RECUS AU COURS DE L'EXERCICE N | F17: C
A20: AUTRES FONDS RECUS AU COURS DE L'EXERCICE N | F20: D
A23: VIREMENTS SUR COMPTES OPERATIONNELS | F23: E
A26: DEPENSES DE L'EXERCICE N | F26: F
A29: TRESORERIE EN FIN D'EXERCICE N (A+B+C+D-E-F) | F29: G | G29: =+G11+G14+G17+G20-G23-G26 -> 0
A32: PAIEMENTS EN INSTANCE | F32: H
A35: TRESORERIE NET DES PAIEMENTS EN INSTANCE (G-H) | F35: I | G35: =+G29-G32 -> 0

Sheet TEB
A1: - 7 -
G2: TABLEAU EXECUTION BUDGETAIRE PAGE 1/1
A3: Dénomination sociale : | B3: =+TRC!B3 -> DSO Services
A4: Adresse : | B4: =+TRC!B4 -> Rue Alphamoi Djénèpo, secteur 01, Bobo-Dioulasso, Burkina Faso | G4: Sigle usuel : | H4: =+TRC!G4 -> DSO Services
A5: N° IFU du contribuable : | B5: =+TRC!B5 -> 00000101A | D5: Exercice clos le | E5: =+TRC!D5 -> 45657 | G5: Durée (en mois) : | H5: =+TRC!G5 -> 12
A6: N° de télédéclarant (NES) : | B6: =+TRC!B6 -> Néant
A9: TABLEAU D'EXECUTION BUDGETAIRE
A11: TABLEAU SUIVI EXECUTION BUDGETAIRE DU 01/01/202N AU 31/12/202N
A14: Code | B14: Libellé | C14: Budget de l'exercice | D14: Décaissement | E14: Engagement | F14: Réalisation | G14: Crédit Disponible | H14: Exécution budget (%)
C15: 1 | D15: 2 | E15: 3 | F15: 4=2+3 | G15: 5=1-4 | H15: 4\1
F16: =+D16+E16 -> 0 | G16: =+C16-F16 -> 0 | H16: =IFERROR(+F16/C16,"")
F17: =+D17+E17 -> 0 | G17: =+C17-F17 -> 0 | H17: =IFERROR(+F17/C17,"")
F18: =+D18+E18 -> 0 | G18: =+C18-F18 -> 0 | H18: =IFERROR(+F18/C18,"")
F19: =+D19+E19 -> 0 | G19: =+C19-F19 -> 0 | H19: =IFERROR(+F19/C19,"")
F20: =+D20+E20 -> 0 | G20: =+C20-F20 -> 0 | H20: =IFERROR(+F20/C20,"")
F21: =+D21+E21 -> 0 | G21: =+C21-F21 -> 0 | H21: =IFERROR(+F21/C21,"")
F22: =+D22+E22 -> 0 | G22: =+C22-F22 -> 0 | H22: =IFERROR(+F22/C22,"")
F23: =+D23+E23 -> 0 | G23: =+C23-F23 -> 0 | H23: =IFERROR(+F23/C23,"")
F24: =+D24+E24 -> 0 | G24: =+C24-F24 -> 0 | H24: =IFERROR(+F24/C24,"")
F25: =+D25+E25 -> 0 | G25: =+C25-F25 -> 0 | H25: =IFERROR(+F25/C25,"")
F26: =+D26+E26 -> 0 | G26: =+C26-F26 -> 0 | H26: =IFERROR(+F26/C26,"")
F27: =+D27+E27 -> 0 | G27: =+C27-F27 -> 0 | H27: =IFERROR(+F27/C27,"")
... F44: =+D44+E44 -> 0 | G44: =+C44-F44 -> 0 | H44: =IFERROR(+F44/C44,"")
A45: TOTAL | C45: =SUM(C16:C44) -> 0 | D45: =SUM(D16:D44) -> 0 | E45: =SUM(E16:E44) -> 0 | F45: =SUM(F16:F44) -> 0 | G45: =SUM(G16:G44) -> 0 | H45: =SUM(H16:H44) -> 0
A47: Remplir, code et libellé, suivant la nomenclature budgétaire du projet
A48: (a) Remplir, code et libellé, suivant la nomenclature budgétaire du projet.
A49: (b) Le plan comptable doit être conçu en tenant compte du budget du projet.
A50: Cette rubrique sera remplie au vu du budget de l’exercice du projet compte par compte.
A51: © Si le plan comptable est conçu sur la base du budget, indiquer le décaissement pour chaque item qui doit correspondre à la somme algébrique suivante :
A52: ●mouvement débit balance N des compte immobilisations (compte2) a
A53: L’exception des virements de compte à compte +( solde créditeur N-1 du compte 481- solde créditeur N du compte 481)
A54: · Mouvement débit balance N des comptes de charges (comptes 6 et 8)+ (solde créditeur N-1 du compte 40 sauf 409-solde créditeur N du compte 40 sauf 409) +(solde débiteur balance N du compte 409-solde débiteur balance N-1 du compte 409) .
A55: (d) le montant de l’engagement pour chaque item doit correspondre :
A56: · Au solde créditeur balance N des comptes fournisseurs d’exploitation
A57: (compte 40) et d’investissement (compte 481) ,
A58: · Bons de commande des biens et services remis aux fournisseurs au cours de l’exercice budgétaire non exécutés,
A59: · Contrats signés par les parties prenantes au cours de l’exercice budgétaire non exécutés .

Sheet BILAN PAYSAGE
A1: - 8 -
C2: =+TEB!B3 -> DSO Services | K2: BILAN SYSTÈME NORMAL PAGE 1/1
B3: Dénomination sociale de l'entité : | C3: =+TEB!B4 -> Rue Alphamoi Djénèpo, secteur 01, Bobo-Dioulasso, Burkina Faso
B4: Adresse : | C4: =+TEB!B5 -> 00000101A | K4: Sigle usuel : | L4: =+TEB!H4 -> DSO Services
B5: N° IFU du contribuable : | C5: =+TEB!B6 -> Néant | G5: Exercice clos le : | I5: =+TEB!E5 -> 45657 | K5: Durée (en mois) : | L5: =+TEB!H5 -> 12
B6: N° de télédéclarant (NES):
A8: =CONCATENATE("Bilan au 31 Décembre"&" "&TEXT('INFORMATIONS GENERALES'!J13,"aaaa")) -> Bilan au 31 Décembre 2024
A10: REF | B10: ACTIF | C10: NOTE | F10: EXERCICE AU 31/12/ N | G10: EXERCICE AU 31/12/N-1 | H10: REF | I10: PASSIF | J10: NOTE | K10: EXERCICE AU 31/12/N | L10: EXERCICE AU 31/12/N-1
D11: Brut | E11: Amort/Dépréc | F11: Net | G11: Net | K11: Net | L11: Net
A12: AA | B12: Immobilisations incorporelles | D12: =SUMIF('Balance N'!A:A,21,'Balance N'!O:O) -> 0 | E12: =SUMIF('Balance N'!B:B,281,'Balance N'!P:P)+SUMIF('Balance N'!B:B,291,'Balance N'!P:P) -> 0 | F12: =D12-E12 -> 0 | G12: =SUMIF('Balance N-1'!A:A,21,'Balance N-1'!O:O)-(SUMIF('Balance N-1'!B:B,281,'Balance N-1'!P:P)+SUMIF('Balance N-1'!B:B,291,'Balance N-1'!P:P)) -> 0 | H12: CA | I12: Fonds affectés aux investissements | K12: =SUMIF('Balance N'!A:A,16,'Balance N'!P:P) -> 0 | L12: =SUMIF('Balance N-1'!A:A,16,'Balance N-1'!P:P) -> 0
A13: AB | B13: Terrains et bâtiments | D13: =SUMIF('Balance N'!A:A,22,'Balance N'!O:O)+SUMIF('Balance N'!B:B,231,'Balance N'!O:O)+SUMIF('Balance N'!B:B,233,'Balance N'!O:O)+SUMIF('Balance N'!C:C,2391,'Balance N'!O:O)+SUMIF('Balance N'!C:C,2392,'Balance N'!O:O)+SUMIF('Balance N'!C:C,2393,'Balance N'!O:O)+SUMIF('Balance N'!C:C,2396,'Balance N'!O:O) -> 0 | E13: =SUMIF('Balance N'!B:B,282,'Balance N'!P:P)+SUMIF('Balance N'!C:C,2831,'Balance N'!P:P)+SUMIF('Balance N'!C:C,2832,'Balance N'!P:P)+SUMIF('Balance N'!C:C,2833,'Balance N'!P:P)+SUMIF('Balance N'!B:B,292,'Balance N'!P:P)+SUMIF('Balance N'!C:C,2931,'Balance N'!P:P)+SUMIF('Balance N'!C:C,2932,'Balance N'!P:P)+SUMIF('Balance N'!C:C,2933,'Balance N'!P:P)+SUMIF('Balance N'!C:C,2939,'Balance N'!P:P) -> 0 | F13: =D13-E13 -> 0 | G13: =SUMIF('Balance N-1'!A:A,22,'Balance N-1'!O:O)+SUMIF('Balance N-1'!B:B,231,'Balance N-1'!O:O)+SUMIF('Balance N-1'!B:B,233,'Balance N-1'!O:O)+SUMIF('Balance N-1'!C:C,2391,'Balance N-1'!O:O)+SUMIF('Balance N-1'!C:C,2392,'Balance N-1'!O:O)+SUMIF('Balance N-1'!C:C,2393,'Balance N-1'!O:O)+SUMIF('Balance N-1'!C:C,2396,'Balance N-1'!O:O)-(SUMIF('Balance N-1'!B:B,282,'Balance N-1'!P:P)+SUMIF('Balance N-1'!C:C,2831,'Balance N-1'!P:P)+SUMIF('Balance N-1'!C:C,2832,'Balance N-1'!P:P)+SUMIF('Balance N-1'!C:C,2833,'Balance N-1'!P:P)+SUMIF('Balance N-1'!B:B,292,'Balance N-1'!P:P)+SUMIF('Balance N-1'!C:C,2931,'Balance N-1'!P:P)+SUMIF('Balance N-1'!C:C,2932,'Balance N-1'!P:P)+SUMIF('Balance N-1'!C:C,2933,'Balance N-1'!P:P)+SUMIF('Balance N-1'!C:C,2939,'Balance N-1'!P:P)) -> 0 | H13: CB | I13: Repot à nouveau (+ou-) | K13: =SUMIF('Balance N'!B:B,121,'Balance N'!P:P)-SUMIF('Balance N'!B:B,129,'Balance N'!O:O) -> 0 | L13: =SUMIF('Balance N-1'!B:B,121,'Balance N-1'!P:P)-SUMIF('Balance N-1'!B:B,129,'Balance N-1'!O:O) -> 0
A14: AC | B14: Aménagements, agencements et installations | D14: =SUMIF('Balance N'!B:B,234,'Balance N'!O:O)+SUMIF('Balance N'!B:B,235,'Balance N'!O:O)+SUMIF('Balance N'!B:B,238,'Balance N'!O:O)+SUMIF('Balance N'!C:C,2394,'Balance N'!O:O)+SUMIF('Balance N'!C:C,2395,'Balance N'!O:O)+SUMIF('Balance N'!C:C,2398,'Balance N'!O:O) -> 0 | E14: =SUMIF('Balance N'!C:C,2834,'Balance N'!P:P)+SUMIF('Balance N'!C:C,2835,'Balance N'!P:P)+SUMIF('Balance N'!C:C,2838,'Balance N'!P:P)+SUMIF('Balance N'!C:C,2934,'Balance N'!P:P)+SUMIF('Balance N'!C:C,2935,'Balance N'!P:P)+SUMIF('Balance N'!C:C,2938,'Balance N'!P:P)+SUMIF('Balance N'!C:C,2939,'Balance N'!P:P) -> 0 | F14: =D14-E14 -> 0 | G14: =SUMIF('Balance N-1'!B:B,234,'Balance N-1'!O:O)+SUMIF('Balance N-1'!B:B,235,'Balance N-1'!O:O)+SUMIF('Balance N-1'!B:B,238,'Balance N-1'!O:O)+SUMIF('Balance N-1'!C:C,2394,'Balance N-1'!O:O)+SUMIF('Balance N-1'!C:C,2395,'Balance N-1'!O:O)+SUMIF('Balance N-1'!C:C,2398,'Balance N-1'!O:O)-(SUMIF('Balance N-1'!C:C,2834,'Balance N-1'!P:P)+SUMIF('Balance N-1'!C:C,2835,'Balance N-1'!P:P)+SUMIF('Balance N-1'!C:C,2838,'Balance N-1'!P:P)+SUMIF('Balance N-1'!C:C,2934,'Balance N-1'!P:P)+SUMIF('Balance N-1'!C:C,2935,'Balance N-1'!P:P)+SUMIF('Balance N-1'!C:C,2938,'Balance N-1'!P:P)+SUMIF('Balance N-1'!C:C,2939,'Balance N-1'!P:P)) -> 0 | H14: CC | I14: solde des opérations de l'exercice | K14: =+'Compte d''exploitation'!H31 -> 0 | L14: =+'Compte d''exploitation'!I31 -> 0
A15: AD | B15: Matériel, mobilier et actif biologiques | C15: 3 | D15: =SUMIF('Balance N'!A:A,24,'Balance N'!O:O)-SUMIF('Balance N'!B:B,245,'Balance N'!O:O)-SUMIF('Balance N'!C:C,2495,'Balance N'!O:O) -> 0 | E15: =SUMIF('Balance N'!B:B,284,'Balance N'!P:P)-SUMIF('Balance N'!C:C,2845,'Balance N'!P:P)+SUMIF('Balance N'!B:B,294,'Balance N'!P:P)-SUMIF('Balance N'!C:C,2945,'Balance N'!P:P)-SUMIF('Balance N'!C:C,2949,'Balance N'!P:P) -> 0 | F15: =D15-E15 -> 0 | G15: =SUMIF('Balance N-1'!A:A,24,'Balance N-1'!O:O)-SUMIF('Balance N-1'!B:B,245,'Balance N-1'!O:O)-SUMIF('Balance N-1'!C:C,2495,'Balance N-1'!O:O)-(SUMIF('Balance N-1'!B:B,284,'Balance N-1'!P:P)-SUMIF('Balance N-1'!C:C,2845,'Balance N-1'!P:P)+SUMIF('Balance N-1'!B:B,294,'Balance N-1'!P:P)-SUMIF('Balance N-1'!C:C,2945,'Balance N-1'!P:P)-SUMIF('Balance N-1'!C:C,2949,'Balance N-1'!P:P)) -> 0 | H15: CD | I15: Subvention d'investissement | J15: 9 | K15: =SUMIF('Balance N'!A:A,14,'Balance N'!P:P) -> 0 | L15: =SUMIF('Balance N-1'!A:A,14,'Balance N-1'!P:P) -> 0
A16: AE | B16: Matériel de transport | D16: =SUMIF('Balance N'!B:B,245,'Balance N'!O:O)+SUMIF('Balance N'!C:C,2495,'Balance N'!O:O) -> 0 | E16: =SUMIF('Balance N'!C:C,2845,'Balance N'!P:P)+SUMIF('Balance N'!C:C,2945,'Balance N'!P:P)+SUMIF('Balance N'!C:C,2949,'Balance N'!P:P) -> 0 | F16: =D16-E16 -> 0 | G16: =SUMIF('Balance N-1'!B:B,245,'Balance N-1'!O:O)+SUMIF('Balance N-1'!C:C,2495,'Balance N-1'!O:O)-(SUMIF('Balance N-1'!C:C,2845,'Balance N-1'!P:P)+SUMIF('Balance N-1'!C:C,2945,'Balance N-1'!P:P)+SUMIF('Balance N-1'!C:C,2949,'Balance N-1'!P:P)) -> 0 | H16: CZ | I16: TOTAL RESSOURCES PROPRES ET ASSIMILES | K16: =SUM(K12:K15) -> 0 | L16: =SUM(L12:L15) -> 0
A17: AF | B17: Avances et acomptes versés sur immobilisations | D17: =SUMIF('Balance N'!A:A,25,'Balance N'!O:O) -> 0 | E17: =SUMIF('Balance N'!B:B,295,'Balance N'!P:P) -> 0 | F17: =D17-E17 -> 0 | G17: =SUMIF('Balance N-1'!A:A,25,'Balance N-1'!O:O)-(SUMIF('Balance N-1'!B:B,295,'Balance N-1'!P:P)) -> 0 | H17: DA | I17: Emprunts et assimilées | K17: =SUMIF('Balance N'!A:A,18,'Balance N'!P:P) -> 0 | L17: =SUMIF('Balance N-1'!A:A,18,'Balance N-1'!P:P) -> 0
A18: AG | B18: Dépôts et cautionnements | D18: =SUMIF('Balance N'!B:B,275,'Balance N'!O:O) -> 0 | E18: =SUMIF('Balance N'!C:C,2975,'Balance N'!P:P) -> 0 | F18: =D18-E18 -> 0 | G18: =SUMIF('Balance N-1'!B:B,275,'Balance N-1'!O:O)-(SUMIF('Balance N-1'!C:C,2975,'Balance N-1'!P:P)) -> 0 | H18: DB | I18: Provisions pour risques et charges | K18: =SUMIF('Balance N'!A:A,19,'Balance N'!P:P) -> 0 | L18: =SUMIF('Balance N-1'!A:A,19,'Balance N-1'!P:P) -> 0
A19: AH | B19: Autre immobilisations corporelles et financières | D19: =SUMIF('Balance N'!A:A,26,'Balance N'!O:O)+SUMIF('Balance N'!A:A,27,'Balance N'!O:O)-SUMIF('Balance N'!B:B,275,'Balance N'!O:O) -> 0 | E19: =SUMIF('Balance N'!B:B,296,'Balance N'!P:P)+SUMIF('Balance N'!B:B,297,'Balance N'!P:P)-SUMIF('Balance N'!C:C,2975,'Balance N'!P:P) -> 0 | F19: =D19-E19 -> 0 | G19: =SUMIF('Balance N-1'!A:A,26,'Balance N-1'!O:O)+SUMIF('Balance N-1'!A:A,27,'Balance N-1'!O:O)-SUMIF('Balance N-1'!B:B,275,'Balance N-1'!O:O)-(SUMIF('Balance N-1'!B:B,296,'Balance N-1'!P:P)+SUMIF('Balance N-1'!B:B,297,'Balance N-1'!P:P)-SUMIF('Balance N-1'!C:C,2975,'Balance N-1'!P:P)) -> 0 | H19: DC | I19: TOTAL DETTES FINANCIERES ET RESSOURCES ASSIMILEES | K19: =SUM(K17:K18) -> 0 | L19: =SUM(L17:L18) -> 0
A20: AZ | B20: TOTAL ACTIF IMMOBILISE | D20: =SUM(D12:D19) -> 0 | E20: =SUM(E12:E19) -> 0 | F20: =SUM(F12:F19) -> 0 | G20: =SUM(G12:G19) -> 0 | H20: DD | I20: TOTAL RESSOURCES STABLES | K20: =K16+K19 -> 0 | L20: =L16+L19 -> 0
A21: AI | B21: Actif circulant HAO | C21: 3 | D21: =SUMIF('Balance N'!B:B,485,'Balance N'!O:O) -> 0 | E21: =SUMIF('Balance N'!B:B,498,'Balance N'!P:P) -> 0 | F21: =D21-E21 -> 0 | G21: =SUMIF('Balance N-1'!B:B,485,'Balance N-1'!O:O)-(SUMIF('Balance N-1'!B:B,498,'Balance N-1'!P:P)) -> 0 | H21: DE | I21: Dette circulanttes HAO | K21: =SUMIF('Balance N'!B:B,481,'Balance N'!P:P)+SUMIF('Balance N'!B:B,484,'Balance N'!P:P)+SUMIF('Balance N'!B:B,4998,'Balance N'!P:P) -> 0 | L21: =SUMIF('Balance N-1'!B:B,481,'Balance N-1'!P:P)+SUMIF('Balance N-1'!B:B,484,'Balance N-1'!P:P)+SUMIF('Balance N-1'!B:B,4998,'Balance N-1'!P:P) -> 0
A22: AJ | B22: Stocks et encours | D22: =SUMIF('Balance N'!A:A,31,'Balance N'!O:O)+SUMIF('Balance N'!A:A,32,'Balance N'!O:O)+SUMIF('Balance N'!A:A,33,'Balance N'!O:O)+SUMIF('Balance N'!A:A,34,'Balance N'!O:O)+SUMIF('Balance N'!A:A,35,'Balance N'!O:O)+SUMIF('Balance N'!A:A,36,'Balance N'!O:O)+SUMIF('Balance N'!A:A,37,'Balance N'!O:O)+SUMIF('Balance N'!A:A,38,'Balance N'!O:O) -> 0 | E22: =SUMIF('Balance N'!A:A,39,'Balance N'!P:P) -> 0 | F22: =D22-E22 -> 0 | G22: =(SUMIF('Balance N-1'!A:A,31,'Balance N-1'!O:O)+SUMIF('Balance N-1'!A:A,32,'Balance N-1'!O:O)+SUMIF('Balance N-1'!A:A,33,'Balance N-1'!O:O)+SUMIF('Balance N-1'!A:A,34,'Balance N-1'!O:O)+SUMIF('Balance N-1'!A:A,36,'Balance N-1'!O:O)+SUMIF('Balance N-1'!A:A,38,'Balance N-1'!O:O))-SUMIF('Balance N-1'!A:A,39,'Balance N-1'!P:P) -> 0 | H22: DF | I22: Fonds d'administration | K22: =SUMIF('Balance N'!A:A,46,'Balance N'!P:P) -> 0 | L22: =SUMIF('Balance N-1'!A:A,46,'Balance N-1'!P:P) -> 0
A23: AK | B23: fournisseurs débiteurs | C23: 3 | D23: =SUMIF('Balance N'!B:B,409,'Balance N'!O:O) -> 0 | E23: =SUMIF('Balance N'!B:B,490,'Balance N'!P:P) -> 0 | F23: =D23-E23 -> 0 | G23: =SUMIF('Balance N-1'!A:A,40,'Balance N-1'!O:O)-(SUMIF('Balance N-1'!B:B,490,'Balance N-1'!P:P)) -> 0 | H23: DG | I23: Fournisseurs | K23: =SUMIF('Balance N'!A:A,40,'Balance N'!P:P) -> 0 | L23: =SUMIF('Balance N-1'!A:A,40,'Balance N-1'!P:P) -> 0
A24: AL | B24: Clients-usagers | C24: 3 | D24: =SUMIF('Balance N'!A:A,41,'Balance N'!O:O)-SUMIF('Balance N'!B:B,419,'Balance N'!O:O) -> 0 | E24: =SUMIF('Balance N'!B:B,491,'Balance N'!P:P) -> 0 | F24: =D24-E24 -> 0 | G24: =(SUMIF('Balance N-1'!A:A,41,'Balance N-1'!O:O)-SUMIF('Balance N-1'!B:B,419,'Balance N-1'!O:O))-(SUMIF('Balance N-1'!B:B,491,'Balance N-1'!P:P)) -> 0 | H24: DH | I24: Autres dettes | J24: 10 | K24: =SUMIF('Balance N'!A:A,42,'Balance N'!P:P)+SUMIF('Balance N'!A:A,43,'Balance N'!P:P)+SUMIF('Balance N'!A:A,44,'Balance N'!P:P)+SUMIF('Balance N'!A:A,47,'Balance N'!P:P)-SUMIF('Balance N'!B:B,479,'Balance N'!P:P)-SUMIF('Balance N'!C:C,4998,'Balance N'!P:P)+SUMIF('Balance N'!A:A,41,'Balance N'!P:P) -> 0 | L24: =SUMIF('Balance N-1'!A:A,42,'Balance N-1'!P:P)+SUMIF('Balance N-1'!A:A,43,'Balance N-1'!P:P)+SUMIF('Balance N-1'!A:A,44,'Balance N-1'!P:P)+SUMIF('Balance N-1'!A:A,47,'Balance N-1'!P:P)-SUMIF('Balance N-1'!B:B,479,'Balance N-1'!P:P)-SUMIF('Balance N-1'!C:C,4998,'Balance N-1'!P:P)+SUMIF('Balance N-1'!A:A,41,'Balance N-1'!P:P) -> 0
