Workbook
Name _dFin: 42735
Name _soNumFisc: 3201201523617
Name _soSigle: "PYTHAGORE CONSULTAN"

Sheet COUVERTURE
F4: BURKINA FASO
C6: MINISTERE DE L'ECONOMIE DES FINANCES ET DU DEVELOPPEMENT
F8: DIRECTION GENERALE DES IMPOTS
E31: LIASSE SYSTEME NORMAL

Sheet GARDE
B2: BURKINA FASO
B3: MINISTERE DE L'ECONOMIE DES FINANCES ET DU DEVELOPPEMENT
B4: DIRECTION GENERALE DES IMPOTS
C8: CENTRE DE DEPOT DE
C12: ETATS FINANCIERS NORMALISES SYSTEME COMPTABLE OHADA (SYSCOHADA)
E16: EXERCICE CLOS LE
D20: DESIGNATION DE L'ENTITE
B22: DENOMINATION SOCIALE :
B23: (ou nom et prénoms de l'exploitant)
B26: SIGLE USUEL :
B28: ADRESSE COMPLETE :
B30: N° IFU DU CONTRIBUABLE :
B31: N° DE TELEDECLARANT (NES):
B32: SYSTEME NORMAL
B33: Documents déposés | H33: Réservé à la Direction Générale des Impôts
B35: Fiche d'identification et renseignements divers | H35: Date de dépôt
B36: Bilan
B37: Compte de résultat
B38: Tableau des flux de trésorerie
B39: Notes annexes | H39: Nom de l'agent de la DGI ayant réceptionné le dépôt
B40: Etats supplémentaires DGI
B44: Nombre de pages déposées par exemplaire : | H44: Signature de l'agent et cachet du service
B45: Nombre d'exemplaires déposés :

Sheet RECEVABILITE
A1: - 0 -
A3: CONDITIONS DE RECEVABILITE
B5: Entités utilisant des imprimés:
B7: * N'utilisez que des imprimés normalisés
B9: * Remplir chaque page de façon parfaitement lisible sans décalage de lignes
B11: * Ne créer aucune rubrique
B13: * Eviter toute surcharge et donner les explications sur une feuille séparée
B15: * N'utilisez que des codes indiqués dans les tables
B17: * N'utilisez que des imprimés en noir et blanc
B20: Entités produisant les états financiers à l'aide de l'outil informatique
B22: * Reproduire à l'identique la contexture des imprimés normalisés
B24: * Fournir une liasse comprenant à la fois : la fiche d'identification et renseignements divers et les états financiers correspondant au système comptable
B26: * Ne créer aucune rubrique
B28: * N'utilisez que des codes indiqués dans les tables
... B37: Les Notes annexes non chiffrées doivent êtres supprimées. Cependant, elles devront être indiquées dans la Fiche récapitulative des Notes Annexes.

Sheet NOTE36 (TABLE DES CODES)
A1: - 0 -
H2: NOTE 36 SYSTEME NORMAL
A3: Dénomination sociale de l'entité : | C3: =GARDE!D22 -> 0
A4: Adresse : | B4: =GARDE!C28 -> 0 | H4: Sigle usuel: | I4: =GARDE!C26 -> 0
A5: N° IFU du contribuable : | C5: =GARDE!D30 -> 0 | E5: Exercice clos le : | G5: =GARDE!E17 -> 0 | H5: Durée (en mois) : | I5: ='FICHE R1'!U5 -> 0
A6: N° de télédéclarant (NES): | C6: =GARDE!D31 -> 0
A7: NOTE 36 : TABLE DES CODES
A9: 1- Code forme juridique (1) | F9: 3- Code pays du siège social
A11: Société Anonyme (SA) à participation publique | D11: 0 | E11: 0
F12: Pays UEMOA (2)
A13: Société Anonyme (SA) | D13: 0 | E13: 1
F14: Pays CEMAC (3)
A15: Société par Actions Simplifiée (SAS) | D15: 0 | E15: 2
F16: Autres pays OHADA (4)
A17: Société à Responsabilité Limitée (SARL) | D17: 0 | E17: 3 | F17: Afrique du Sud | I17: 2 | J17: 0
F18: Autres pays africains | I18: 2 | J18: 1
A19: Société en Commandite Simple (SCS) | D19: 0 | E19: 4
F20: Suisse | I20: 2 | J20: 2
A21: Société en Nom Collectif (SNC) | D21: 0 | E21: 5
F22: France | I22: 2 | J22: 3
A23: Société en Participation (SP) | D23: 0 | E23: 6
F24: Autres pays de l'Union Européenne | I24: 3 | J24: 9
A25: Groupement d'Intérêt Economique (GIE) | D25: 0 | E25: 7
F26: U.S.A. | I26: 4 | J26: 0
A27: Association | D27: 0 | E27: 8
F28: Canada | I28: 4 | J28: 1
A29: Autre forme juridique (à préciser) | D29: 0 | E29: 9 | F29: Brésil | I29: 4 | J29: 3
F30: Autres pays américains | I30: 4 | J30: 9
A31: 2 - Code régime fiscal
F32: Chine | I32: 5 | J32: 0
A33: Réel normal | E33: 1 | F33: Inde | I33: 5 | J33: 2
F34: Liban | I34: 5 | J34: 3
A35: Réel simplifié | E35: 2 | F35: Autres pays asiatiques | I35: 5 | J35: 9
F36: Russie | I36: 6 | J36: 0
A37: CME | E37: 3
F38: Autres pays | I38: 9 | J38: 9
A39: AUTRE | E39: 4
F40: (Zone monétaire = Zone franc CFA)
A42: (1) Remplacer le premier 0 par 1 si l'entreprise bénéficie d'un agrément prioritaire
A43: (2) Bénin = 01 ; Burkina = 02 ; Côte d'Ivoire = 03 ; Guinée Bissau = 04 ; Mali = 05 ; Niger = 06 ; Sénégal = 07 ; Togo = 08
...

Sheet NOTE36 Suite(nomenclature)
A1: NOTE 36 (suite Nomenclature)
A2: Sélectionner la ou les codes activités selon le découpage de votre chiffre d'affaires pour le renseignement de la fiche R2
A6: CODES ACTIVITES ECONOMIQUES
A7: Agriculture vivrière | H7: Industries du caoutchouc et des plastiques
A8: 001 001 Culture céréalière | H8: 022 001 Fabrication du caoutchouc naturel
A9: 001 002 Culture de tubercules et plantains | H9: 022 002 Industries du caoutchouc
A10: 001 003 Culture de légumes | H10: 022 003 Fabrication de matières plastiques
A11: 001 004 Culture de condiments | H11: Fabrication d’autres produits minéraux non métalliques et de matériaux
A12: 001 005 Culture de fruits | H12: de construction
A13: 001 006 Culture d’autres produits de l’Agriculture vivrière | H13: 023 001 Industrie du verre
A14: Agriculture industrielle et d’exportation | H14: 023 002 Fabrication de produits minéraux pour la construction
A15: 002 001 Culture de canne à sucre | H15: 023 003 Fabrication d’autres produits minéraux non métalliques
A16: 002 002 Culture d’arachide d’huilerie | H16: Métallurgie et travail des métaux
A17: 002 003 Culture d’arachide de bouche | H17: 024 001 Métallurgie
A18: 002 004 Culture de tabac | H18: 024 002 Travail des métaux
... A56: 012 000 Industries laitières | H56: Postes, télécommunications

Sheet FICHE R1
A1: - 0 -
R2: FICHE R1
A3: Dénomination sociale de l'entité : | E3: =GARDE!D22 -> 0
A4: Adresse : | D4: =GARDE!C28 -> 0 | P4: Sigle usuel : | S4: =GARDE!C26 -> 0
A5: N° IFU du contribuable : | E5: =GARDE!D30 -> 0 | H5: Exercice clos le : | Q5: Durée (en mois) :
A6: N° de télédéclarant (NES) : | E6: =GARDE!D31 -> 0
A7: FICHE R1 : FICHE D'IDENTIFICATION ET RENSEIGNEMENTS DIVERS 1
A8: ZA | C8: EXERCICE COMPTABLE : | M8: DU: | R8: AU:
A10: ZB | C10: DATE D'ARRETE EFFECTIF DES COMPTES : | T10: ZD
A12: ZC | C12: EXERCICE PRECEDENT CLOS LE : | K12: DUREE EXERCICE PRECEDENT EN MOIS :
A14: ZE | J14: ZF
C15: Greffe | D15: N°Registre du Commerce | K15: N° Répertoire des entités
A17: ZG | E17: ZH | P17: ZI
C18: N° de caisse sociale | F18: N° Code Importateur | Q18: Code activité principale
A20: ZJ
C21: Désignation de l'entité | Q21: Sigle
A23: ZK
C24: N° de téléphone | E24: Adresse e-mail | K24: Code | N24: Boîte Postale | Q24: Ville
A26: ZL
C27: Adresse géographique complète (Immeuble, rue, quartier, ville, pays)
P28: ZN
A29: ZM
C30: Désignation précise de l'activité principale exercée par l'entité | P30: % Capacité production utile
A32: ZO
C33: Nom, adresse, téléphone, adresse e-mail et qualité de la personne à contacter en cas de demande
A35: ZP
C36: Nom, adresse, téléphone et e-mail du salarié de l'entité ou
C37: du professionnel comptable inscrit à l'Ordre des Experts-comptables ayant établi les états financiers
A39: ZQ
A43: ZR
C44: Nom, adresse, téléphone, e-mail et numéro d'inscription à l'Ordre des Experts-comptables
C45: de l'Expert comptablble ayant délivré l'attestation d'exécution de la mission du commissariat aux comptes
A47: ZS | O47: Non | T47: Oui
N48: Etats financiers approuvés par l'Assemblée Générale (cocher la case)
J49: ZW
A50: ZT | J50: Domiciliations bancaires
C51: Nom du signataire des états financiers | J51: Banque | Q51: Numéro de compte
A53: ZU
C54: Qualité du signataire des états financiers
A56: ZV
...

Sheet FICHE R2
A1: - 0 -
AG2: FICHE R2
A3: Dénomination sociale de l'entité : | I3: ='FICHE R1'!E3 -> 0
A4: Adresse : | E4: ='FICHE R1'!D4 -> 0 | AC4: Sigle usuel : | AI4: ='FICHE R1'!S4 -> 0
A5: N° IFU du contribuable : | I5: ='FICHE R1'!E5 -> 0 | Q5: Exercice clos le : | W5: ='FICHE R1'!J5 -> 0 | AC5: Durée (en mois) : | AI5: ='FICHE R1'!U5 -> 0
A6: N° de télédéclarant (NES) : | I6: ='FICHE R1'!E6 -> 0
A7: FICHE R2 : FICHE D'IDENTIFICATION ET RENSEIGNEMENTS DIVERS 2
V8: Contrôle de l'Entité (cocher la case)
A9: ZX | D9: Forme juridique (1) : | V9: ZZ5 | X9: Entité sous contrôle public
A11: ZY | D11: Régime fiscal (1) : | V11: ZZ6 | X11: Entité sous contrôle privé national
A13: ZZ1 | D13: Pays du siège social (1) : | V13: ZZ7 | X13: Entité sous contrôle privé étranger
A15: ZZ2 | D15: Nombre d'établissements dans le pays :
A17: ZZ3 | D17: Nombre d'établissements hors du pays pour
D18: lesquels une comptabilité distincte est tenue :
A20: ZZ4 | D20: Première année d'exercice dans le pays :
A23: ACTIVITE DE L'ENTITE
A25: Désignation de l'activité (2) | P25: Code nomenclature d'activité (1) | Y25: Chiffre d'affaires HT (CA HT) ou Valeur ajoutée (VA) (3) (4) | AI25: % activité dans le CA HT ou la VA
AJ35: 0
AJ38: 0
AJ41: 0
AJ44: 0
AJ47: 0
AJ50: 0
A52: Divers (4)
P54: TOTAL | Z54: =Z29+Z32+Z35+Z38+Z41+Z44+Z47+Z50+Z52 -> 0 | AI54: =AI29+AI32+AI35+AI38+AI41+AI44+AI47+AI50+AI52 -> 0
A57: (1) Note 36 Suite (Nomenclature)
A58: (2) Lister de manière précise les activités dans l'ordre décroissant du C.A.HT ou de la valeur ajoutée (V.A).
A59: (3) Rayer la mention inutile - Au Burkina Faso, pour les besoins de l'INSD, on préfèrera le chiffre d'affaires.
A60: (4) Indiquer dans la note annexe n°21 "Chiffre d'affaires et autres produits", la liste détaillée des activités classées dans la rubrique "Divers"

Sheet FICHE R3
A1: - 0 -
I2: FICHE R3
A3: Dénomination sociale de l'entité : | C3: ='FICHE R1'!E3 -> 0
A4: Adresse : | B4: ='FICHE R1'!D4 -> 0 | H4: Sigle usuel : | J4: ='FICHE R1'!S4 -> 0
A5: N° IFU du contribuable : | C5: ='FICHE R1'!E5 -> 0 | E5: Exercice clos le : | F5: ='FICHE R1'!J5 -> 0 | H5: Durée (en mois) : | J5: ='FICHE R1'!U5 -> 0
A6: N° de télédéclarant (NES) : | C6: ='FICHE R1'!E6 -> 0
A7: FICHE R3 : FICHE D'IDENTIFICATION ET RENSEIGNEMENTS DIVERS 3
A8: DIRIGEANTS (1)
A10: Nom et Prénoms | C10: Nationalité | D10: Autres nationalités (à préciser) (2) | E10: Qualité | F10: N° d'identification fiscale | H10: Adresse (BP, ville, pays, adresse géographique et adresse email)
A22: (1) Dirigeants = Président Directeur Général, Directeur Général, Administrateur Général, Gérant, Autres.
A23: (2) En cas de double nationalité
A24: MEMBRES DU CONSEIL D'ADMINISTRATION
A26: Nom et Prénoms | C26: Structure représentée | E26: Qualité | G26: Adresse (BP, ville, pays, adresse géographique et adresse email)

Sheet BILAN
A1: - 0 -
L2: BILAN SYSTEME NORMAL PAGE 1/1
A3: Dénomination sociale de l'entité :
A4: Adresse : | L4: Sigle usuel :
A5: N° IFU du contribuable : | I5: Exercice clos le : | L5: Durée (en mois) :
A6: N° de télédéclarant (NES):
A7: BILAN
A8: REF | B8: ACTIF | E8: NOTE | F8: EXERCICE au 31/12/ N | I8: EXERCICE AU 31/12/N-1 | J8: REF | K8: PASSIF | L8: NOTE | M8: EXERCICE AU 31/12/N | N8: EXERCICE AU 31/12/N-1
F10: BRUT | G10: AMORT et DEPREC. | H10: NET | I10: NET | M10: NET | N10: NET
A11: AD | B11: IMMOBILISATIONS INCORPORELLES | E11: 3 | F11: =SUM(F12:F15) -> 0 | G11: =SUM(G12:G15) -> 0 | H11: =SUM(H12:H15) -> 0 | I11: =SUM(I12:I15) -> 0 | J11: CA | K11: Capital | L11: 13
A12: AE | B12: Frais de développement et de prospection | H12: =F12-G12 -> 0 | J12: CB | K12: Apporteurs capital non appelé (-) | L12: 13
A13: AF | B13: Brevets, licences, logiciels et droits similaires | H13: =F13-G13 -> 0 | J13: CD | K13: Primes liées au capital social | L13: 14
A14: AG | B14: Fonds commercial et droit au bail | H14: =F14-G14 -> 0 | J14: CE | K14: Ecarts de réévaluation | L14: 3e
A15: AH | B15: Autres immobilisations incorporelles | H15: =F15-G15 -> 0 | J15: CF | K15: Réserves indisponibles | L15: 14
A16: AI | B16: IMMOBILISATIONS CORPORELLES | E16: 3 | F16: =SUM(F17:F21) -> 0 | G16: =SUM(G17:G21) -> 0 | H16: =SUM(H17:H21) -> 0 | I16: =SUM(I17:I21) -> 0 | J16: CG | K16: Réserves libres | L16: 14
A17: AJ | B17: Terrains (1) dont Placement Net : | H17: =F17-G17 -> 0 | J17: CH | K17: Report à nouveau (+ ou -) | L17: 14
A18: AK | B18: Bâtiments(1) dont Placement Net : | H18: =F18-G18 -> 0 | J18: CJ | K18: Résultat net de l'exercice (bénéfice + ou perte -)
A19: AL | B19: Aménagements, agencements et installations | H19: =F19-G19 -> 0 | J19: CL | K19: Subventions d'investissement | L19: 15
A20: AM | B20: Matériel, mobilier et actifs biologiques | H20: =F20-G20 -> 0 | J20: CM | K20: Provisions réglementées | L20: 15
A21: AN | B21: Matériel de transport | H21: =F21-G21 -> 0 | J21: CP | K21: TOTAL CAPITAUX PROPRES ET RESSOURCES ASSIMILEES | M21: =SUM(M11:M20) -> 0 | N21: =SUM(N11:N20) -> 0
A22: AP | B22: AVANCES ET ACOMPTES VERSES SUR IMMOBILISATIONS | E22: 3 | H22: =F22-G22 -> 0 | J22: DA | K22: Emprunts et dettes financières diverses | L22: 16
A23: AQ | B23: IMMOBILISATIONS FINANCIERES | E23: 4 | F23: =SUM(F24:F25) -> 0 | G23: =SUM(G24:G25) -> 0 | H23: =SUM(H24:H25) -> 0 | I23: =SUM(I24:I25) -> 0 | J23: DB | K23: Dettes de location-acquisition | L23: 16
A24: AR | B24: Titres de participation | H24: =F24-G24 -> 0 | J24: DC | K24: Provisions pour risques et charges | L24: 16
A25: AS | B25: Autres immobilisations financières | H25: =F25-G25 -> 0 | J25: DD | K25: TOTAL DETTES FINANCIERES ET RESSOURCES ASSIMILEES | M25: =SUM(M22:M24) -> 0 | N25: =SUM(N22:N24) -> 0
A26: AZ | B26: TOTAL ACTIF IMMOBILISE | F26: =F11+F16+F22+F23 -> 0 | G26: =G11+G16+G22+G23 -> 0 | H26: =H11+H16+H22+H23 -> 0 | I26: =I11+I16+I22+I23 -> 0 | J26: DF | K26: TOTAL RESSOURCES STABLES | M26: =M21+M25 -> 0 | N26: =N21+N25 -> 0
A27: BA | B27: ACTIF CIRCULANT HAO | E27: 5 | H27: =F27-G27 -> 0 | J27: DH | K27: Dettes circulantes HAO | L27: 5
A28: BB | B28: STOCKS ET ENCOURS | E28: 6 | H28: =F28-G28 -> 0 | J28: DI | K28: Clients, avances reçues | L28: 7
A29: BG | B29: CREANCES ET EMPLOIS ASSIMILES | F29: =F30+F31+F32 -> 0 | G29: =G30+G31+G32 -> 0 | H29: =H30+H31+H32 -> 0 | I29: =I30+I31+I32 -> 0 | J29: DJ | K29: Fournisseurs d'exploitation | L29: 17
A30: BH | B30: Fournisseurs avances versées | E30: 17 | H30: =F30-G30 -> 0 | J30: DK | K30: Dettes fiscales et sociales | L30: 18
A31: BI | B31: Clients | E31: 7 | H31: =F31-G31 -> 0 | J31: DM | K31: Autres dettes | L31: 19
A32: BJ | B32: Autres créances | E32: 8 | H32: =F32-G32 -> 0 | J32: DN | K32: Provisions pour risques et charges à court terme | L32: 19
A33: BK | B33: TOTAL ACTIF CIRCULANT | F33: =F27+F28+F29 -> 0 | G33: =G27+G28+G29 -> 0 | H33: =H27+H28+H29 -> 0 | I33: =I27+I28+I29 -> 0 | J33: DP | K33: TOTAL PASSIF CIRCULANT | M33: =SUM(M27:M32) -> 0 | N33: =SUM(N27:N32) -> 0
A34: BQ | B34: Titres de placement | E34: 9 | H34: =F34-G34 -> 0
A35: BR | B35: Valeurs à encaisser | E35: 10 | H35: =F35-G35 -> 0 | J35: DQ | K35: Banques, crédits d'escompte | L35: 20
A36: BS | B36: Banques, chèques postaux, caisse et assimilés | E36: 11 | H36: =F36-G36 -> 0 | J36: DR | K36: Banques, établissements financiers et crédits de trésorerie | L36: 20
A37: BT | B37: TOTAL TRESORERIE-ACTIF | F37: =SUM(F34:F36) -> 0 | G37: =SUM(G34:G36) -> 0 | H37: =SUM(H34:H36) -> 0 | I37: =SUM(I34:I36) -> 0 | J37: DT | K37: TOTAL TRESORERIE-PASSIF | M37: =SUM(M35:M36) -> 0 | N37: =SUM(N35:N36) -> 0
A38: BU | B38: Ecart de conversion-Actif | E38: 12 | H38: =F38-G38 -> 0 | J38: DV | K38: Ecart de conversion-Passif | L38: 12
A39: BZ | B39: TOTAL GENERAL | F39: =F26+F33+F37+F38 -> 0 | G39: =G26+G33+G37+G38 -> 0 | H39: =H26+H33+H37+H38 -> 0 | I39: =I26+I33+I37+I38 -> 0 | J39: DZ | K39: TOTAL GENERAL | M39: =M26+M33+M37+M38 -> 0 | N39: =N26+N33+N37+N38 -> 0

Sheet RESULTAT
A1: - 0 -
H2: COMPTE DE RESULTAT SYSTEME NORMAL PAGE 1/1
A3: Dénomination sociale de l'entité : | C3: =BILAN!C3 -> 0
A4: Adresse : | C4: =BILAN!C4 -> 0 | I4: Sigle usuel : | J4: =BILAN!N4 -> 0
A5: N° IFU du contribuable : | C5: =BILAN!C6 -> 0 | E5: Exercice clos le : | F5: =BILAN!K5 -> 0 | I5: Durée (en mois) : | J5: =BILAN!N5 -> 0
A6: N° de télédéclarant (NES): | C6: ='FICHE R1'!E6 -> 0
A7: COMPTE DE RESULTAT
A8: REF | B8: LIBELLES | G8: (1) | H8: NOTE | I8: EXERCICE AU 31/12/N | J8: EXERCICE AU 31/12/N-1
I10: NET | J10: NET
A11: TA | B11: Ventes de marchandises | F11: A | G11: + | H11: 21
A12: RA | B12: Achats de marchandises | G12: - | H12: 22
A13: RB | B13: Variation de stocks de marchandises | G13: -/+ | H13: 6
A14: XA | B14: MARGE COMMERCIALE (Somme TA à RB) | I14: =SUM(I11:I13) -> 0 | J14: =IFERROR(SUM(J11:J13),"") -> 0
A15: TB | B15: Ventes de produits fabriqués | F15: B | G15: + | H15: 21
A16: TC | B16: Travaux, services vendus | F16: C | G16: + | H16: 21
A17: TD | B17: Produits accessoires | F17: D | G17: + | H17: 21
A18: XB | B18: CHIFFRE D'AFFAIRES (A + B + C + D) | I18: =I11+I15+I16+I17 -> 0 | J18: =IFERROR(J11+J15+J16+J17,"") -> 0
A19: TE | B19: Production stockée (ou déstockage) | G19: -/+ | H19: 6
A20: TF | B20: Production immobilisée | H20: 21
A21: TG | B21: Subventions d’exploitation | H21: 21
A22: TH | B22: Autres produits | G22: + | H22: 21
A23: TI | B23: Transferts de charges d'exploitation | G23: + | H23: 12
A24: RC | B24: Achats de matières premières et fournitures liées | G24: - | H24: 22
A25: RD | B25: Variation de stocks de matières premières et fournitures liées | G25: -/+ | H25: 6
A26: RE | B26: Autres achats | G26: - | H26: 22
A27: RF | B27: Variation de stocks d’autres approvisionnements | G27: -/+ | H27: 6
A28: RG | B28: Transports | G28: - | H28: 23
A29: RH | B29: Services extérieurs | G29: - | H29: 24
A30: RI | B30: Impôts et taxes | G30: - | H30: 25
A31: RJ | B31: Autres charges | G31: - | H31: 26
A32: XC | B32: VALEUR AJOUTEE (XB +RA+RB) + (somme TE à RJ) | I32: =SUM(I19:I31) +I12+I13+I18 -> 0 | J32: =IFERROR(SUM(J19:J31) +J12+J13+J18,"") -> 0
A33: RK | B33: Charges de personnel | G33: - | H33: 27
A34: XD | B34: EXCEDENT BRUT D'EXPLOITATION (XC+RK) | I34: =I32+I33 -> 0 | J34: =IFERROR(J32+J33,"") -> 0
A35: TJ | B35: Reprises d’amortissements, provisions et dépréciations | G35: + | H35: 28
A36: RL | B36: Dotations aux amortissements, aux provisions et dépréciations | G36: - | H36: 3C&28
A37: XE | B37: RESULTAT D'EXPLOITATION (XD+TJ+ RL) | I37: =I34+I35+I36 -> 0 | J37: =IFERROR(J34+J35+J36,"") -> 0
A38: TK | B38: Revenus financiers et assimilés | G38: + | H38: 29
A39: TL | B39: Reprises de provisions et dépréciations financières | G39: + | H39: 28
A40: TM | B40: Transferts de charges financières | G40: + | H40: 12
A41: RM | B41: Frais financiers et charges assimilées | G41: - | H41: 29
...

Sheet TFT
A1: - 0 -
H2: FLUX DE TRESORERIE SYSTEME NORMAL PAGE 1/1
A3: Dénomination sociale de l'entité : | C3: =BILAN!C3 -> 0
A4: Adresse : | C4: =BILAN!C4 -> 0 | I4: Sigle usuel : | J4: =BILAN!N4 -> 0
A5: N° IFU du contribuable : | C5: =BILAN!C5 -> 0 | E5: Exercice clos le : | F5: =BILAN!K5 -> 0 | I5: Durée (en mois) : | J5: =BILAN!N5 -> 0
A6: N° de télédéclarant (NES): | C6: =BILAN!C6 -> 0
A7: TABLEAU DES FLUX DE TRESORERIE
A8: REF | B8: LIBELLES | H8: NOTE | I8: EXERCICE | J8: EXERCICE
I9: N | J9: N-1
A10: ZA | B10: Trésorerie nette au 1er janvier (Trésorerie actif N-1 - Trésorerie passif N-1) | G10: A
B11: Flux de trésorerie provenant des activités opérationnelles
A12: FA | B12: Capacité d'Autofinancement Globale (CAFG)
A13: FB | B13: - Variation d'actif circulant HAO (1)
A14: FC | B14: - Variation des stocks
A15: FD | B15: - Variation des créances
A16: FE | B16: + Variation du passif circulant (1)
B17: Variation du BF lié aux activités opérationnelles
B18: FB+FC+FD+FE : | C18: =I13+I14+I15+I16 -> 0 | E18: =IFERROR(J13+J14+J15+J16,"") -> 0
A19: ZB | B19: Flux de trésorerie provenant des activités opérationnelles (Somme FA à FE) | G19: B | I19: =SUM(I12:I16) -> 0 | J19: =IFERROR(SUM(J12:J16),"") -> 0
B20: Flux de trésorerie provenant des activités d’investissements
A21: FF | B21: - Décaissements liés aux acquisitions d'immobilisations incorporelles
A22: FG | B22: - Décaissements liés aux acquisitions d'immobilisations corporelles
A23: FH | B23: - Décaissements liés aux acquisitions d'immobilisations financières
A24: FI | B24: + Encaissements liés aux cessions d’immobilisations incorporelles et corporelles
A25: FJ | B25: + Encaissements liés aux cessions d’immobilisations financières
A26: ZC | B26: Flux de trésorerie provenant des activités d’investissement (somme FF à FJ) | G26: C | I26: =SUM(I21:I25) -> 0 | J26: =IFERROR(SUM(J21:J25),"") -> 0
B27: Flux de trésorerie provenant du financement par les capitaux propres
A28: FK | B28: + Augmentations de capital par apports nouveaux
A29: FL | B29: + Subventions d'investissement reçues
A30: FM | B30: - Prélèvements sur le capital
A31: FN | B31: - Dividendes versés
A32: ZD | B32: Flux de trésorerie provenant des capitaux propres (somme FK à FN) | G32: D | I32: =SUM(I28:I31) -> 0 | J32: =IFERROR(SUM(J28:J31),"") -> 0
B33: Trésorerie provenant du financement par les capitaux étrangers
A34: FO | B34: + Emprunts
A35: FP | B35: + Autres dettes financières diverses
A36: FQ | B36: - Remboursements des emprunts et autres dettes financières
A37: ZE | B37: Flux de trésorerie provenant des capitaux étrangers (somme FO à FQ) | G37: E | I37: =SUM(I34:I36) -> 0 | J37: =IFERROR(SUM(J34:J36),"") -> 0
A38: ZF | B38: Flux de trésorerie provenant des activités de financement (D+E) | G38: F | I38: =I32+I37 -> 0 | J38: =IFERROR(J32+J37,"") -> 0
A39: ZG | B39: VARIATION DE LA TRÉSORERIE NETTE DE LA PÉRIODE (B+C+F) | G39: G | I39: =I19+I26+I38 -> 0 | J39: =J19+J26+J38 -> 0
A40: ZH | B40: Trésorerie nette au 31 Décembre (G+A) | G40: H | I40: =I10+I39 -> 0 | J40: =IFERROR(J10+J39,"") -> 0
...

Sheet FICHE R4
A1: - 0 -
I2: FICHE R4
A3: Dénomination sociale de l'entité :
A4: Adresse : | H4: Sigle usuel :
A5: N° IFU du contribuable : | E5: Exercice clos le : | H5: Durée (en mois) :
A6: N° de télédéclarant (NES):
A7: FICHE R4 : FICHE RECAPITULATIVE DES NOTES ANNEXES PRESENTEES (1)
A8: NOTES | B8: INTITULES | I8: A | J8: N/A
A9: NOTE 1 | B9: DETTES GARANTIES PAR DES SURETES REELLES ET LES ENGAGEMENTS FINANCIERS
A10: NOTE 2 | B10: INFORMATIONS OBLIGATOIRES
A11: NOTE 3A | B11: IMMOBILISATIONS BRUTES
A12: NOTE 3B | B12: BIENS PRIS EN LOCATION-ACQUISITION
A13: NOTE 3C | B13: IMMOBILISATIONS : AMORTISSEMENTS
A14: NOTE 3C bis | B14: IMMOBILISATIONS : DEPRECIATIONS
A15: NOTE 3D | B15: IMMOBILISATIONS : PLUS-VALUES ET MOINS VALUE DE CESSION
A16: NOTE 3E | B16: INFORMATIONS SUR LES REEVALUATIONS EFFECTUEES PAR L'ENTITE
A17: NOTE 4 | B17: IMMOBILISATIONS FINANCIERES
A18: NOTE 5 | B18: ACTIF CIRCULANT ET DETTES CIRCULANTES HAO
A19: NOTE 6 | B19: STOCKS ET ENCOURS
A20: NOTE 7 | B20: CLIENTS
... A61: ETATS DGI | B61: ETATS SUPPLEMENTAIRES DGI
A63: (1) les Notes non documentées ne doivent pas être jointes aux états financiers. Leur contenu peut être amélioré par les entités Par ailleurs, dans une note, les lignes non chiffrées doivent être supprimées. Par exemple, dans la note 24 Services Extérieurs, lorsque la ligne sous-traitance générale n'est pas chiffrée, elle ne doit pas figurer dans les notes.
A64: (2) A : Applicable A/N : Non applicable.
A65: Par exemple pour une entité qui n'a pas de stocks et en-cours, elle doit cocher à l'intersection ('ligne NOTE 6' & 'colonne N/A')

Sheet NOTE 1
A1: - 0 -
H2: NOTE 1 SYSTEME NORMAL
A3: Dénomination sociale de l'entité : | C3: ='FICHE R4'!C3 -> 0
A4: Adresse : | B4: ='FICHE R4'!B4 -> 0 | H4: Sigle usuel : | I4: ='FICHE R4'!I4 -> 0
A5: N° IFU du contribuable : | C5: ='FICHE R4'!C5 -> 0 | F5: Exercice clos le : | G5: ='FICHE R4'!F5 -> 0 | H5: Durée (en mois) : | I5: ='FICHE R4'!I5 -> 0
A6: N° de télédéclarant (NES): | C6: ='FICHE R4'!C6 -> 0
A7: NOTE 1: DETTES GARANTIES PAR DES SURETES REELLES ET LES ENGAGEMENTS FINANCIERS
A8: LIBELLES | E8: Note | F8: Montant brut (1) | G8: SURETES REELLES (2)
G9: Hypothèques | H9: Nantissements | I9: Gages/autres
A10: Emprunts et dettes financières diverses : | E10: 16
A11: Emprunts obligataires convertibles
A12: Autres emprunts obligataires
A13: Emprunts et dettes des établissements de crédit
A14: Autres dettes financières
A15: SOUS TOTAL (1) | F15: =SUM(F11:F14) -> 0
A16: Dettes de location-acquisition : | E16: 16
A17: Dettes de crédit-bail immobilier
A18: Dettes de crédit-bail mobilier
A19: Dettes sur contrats de location-vente
A20: Autres dettes sur contrats de location-acquisition
A21: SOUS TOTAL (2) | F21: =SUM(F17:F20) -> 0
A22: Dettes du passif circulant :
A23: Fournisseurs et comptes rattachés | E23: 17
A24: Clients | E24: 7
A25: Personnel | E25: 18
A26: Sécurité sociale et organismes sociaux | E26: 18
A27: Etat | E27: 18
A28: Organismes internationaux | E28: 19
A29: Associés et groupe | E29: 19
A30: Créditeurs divers | E30: 19
A31: SOUS TOTAL (3) | F31: =SUM(F23:F30) -> 0
A32: TOTAL (1) + (2) + (3) | F32: =F15+F21+F31 -> 0
A33: ENGAGEMENTS FINANCIERS | G33: Engagements réciproques | H33: Engagements donnés | I33: Engagements reçus
A34: Engagements consentis à des entités liées
A35: Primes de remboursement des obligations non échues
A36: Avals, cautions, garanties
A37: Hypothèques, nantissements, gages, autres
A38: Effets escomptés non échus
A39: Créances commerciales et professionnelles cédées
A40: Abandons de créances conditionnels
...

Sheet NOTE 2
A1: - 0 -
H2: NOTE 2 SYSTEME NORMAL
A3: Dénomination sociale de l'entité : | C3: ='NOTE 1'!C3 -> 0
A4: Adresse : | B4: ='NOTE 1'!B4 -> 0 | H4: Sigle usuel : | I4: ='NOTE 1'!I4 -> 0
A5: N° IFU du contribuable : | C5: ='NOTE 1'!C5 -> 0 | F5: Exercice clos le : | G5: ='NOTE 1'!G5 -> 0 | H5: Durée (en mois) : | I5: ='NOTE 1'!I5 -> 0
A6: N° de télédéclarant (NES): | C6: ='NOTE 1'!C6 -> 0
A7: NOTE 2: INFORMATIONS OBLIGATOIRES
A8: A - DECLARATION DE CONFORMITE AU SYSCOHADA ET FAITS MARQUANTS DE L'EXERCICE
A10: B - REGLES ET METHODES COMPTABLES
A12: C- DEROGATION AUX POSTULATS ET CONVENTIONS COMPTABLES
A14: D - INFORMATIONS COMPLEMENTAIRES RELATIVES AU BILAN, AU COMPTE DE RESULTAT ET AU TABLEAU DES FLUX DE TRESORERIE
A17: Commentaire :
A18: ● Mentionner les faits marquants après la déclaration de conformité.
A19: Seuls les éléments ayant une incidence comptable significative ou qui misent à la comparabilité des exercices doivent être mentionnés. Par exemple, le lancement d'un produit sur le marché, ou la perte du principal client de l'entité.
A20: ● Décrire les régles et méthodes utilisées pour l'établissement des états financiers et celles utilisées dans le cas de contrat pluri- exercices, de contrats de concession, de l'établissement de comptes intermédiaires, de fusion et opérations assimilées comme indiquées dans les opérations et problèmes spécifiques.

Sheet NOTE 3A
A1: - 0 -
I2: NOTE 3A SYSTEME NORMAL
A3: Dénomination sociale de l'entité : | C3: ='NOTE 1'!C3 -> 0
A4: Adresse : | B4: ='NOTE 1'!B4 -> 0 | I4: Sigle usuel : | J4: ='NOTE 1'!I4 -> 0
A5: N° IFU : | C5: ='NOTE 1'!C5 -> 0 | F5: Exercice clos le : | G5: ='NOTE 1'!G5 -> 0 | I5: Durée (en mois) : | J5: ='NOTE 1'!I5 -> 0
A6: N° de télédéclarant (NES): | C6: ='NOTE 1'!C6 -> 0
A7: NOTE 3A : IMMOBILISATIONS (BRUTES)
A8: SITUATIONS ET MOUVEMENTS | D8: A | E8: AUGMENTATIONS B | H8: DIMINUTIONS C | J8: D = A + B - C
D9: MONTANT BRUT A L'OUVERTURE DE L'EXERCICE | E9: Acquisitions Apports Créations | F9: Virements de poste à poste | G9: Suite à une réévaluation pratiquée au cours de l'exercice | H9: Cessions Scissions Hors service | I9: Virements de poste à poste | J9: MONTANT BRUT A LA CLOTURE DE L'EXERCICE
A10: RUBRIQUES
A11: IMMOBILISATIONS INCORPORELLES | D11: =SUM(D12:D15) -> 0 | E11: =SUM(E12:E15) -> 0 | F11: =SUM(F12:F15) -> 0 | G11: =SUM(G12:G15) -> 0 | H11: =SUM(H12:H15) -> 0 | I11: =SUM(I12:I15) -> 0 | J11: =D11+E11+F11+G11-H11-I11 -> 0
A12: Frais de développement et de prospection | J12: =D12+E12+F12+G12-H12-I12 -> 0
A13: Brevets, licences, logiciels, et droits similaires | J13: =D13+E13+F13+G13-H13-I13 -> 0
A14: Fonds commercial et droit au bail | J14: =D14+E14+F14+G14-H14-I14 -> 0
A15: Autres immobilisations incorporelles | J15: =D15+E15+F15+G15-H15-I15 -> 0
A16: IMMOBILISATIONS CORPORELLES | D16: =SUM(D17:D23) -> 0 | E16: =SUM(E17:E23) -> 0 | F16: =SUM(F17:F23) -> 0 | G16: =SUM(G17:G23) -> 0 | H16: =SUM(H17:H23) -> 0 | I16: =SUM(I17:I23) -> 0 | J16: =D16+E16+F16+G16-H16-I16 -> 0
A17: Terrains hors immeuble de placement | J17: =D17+E17+F17+G17-H17-I17 -> 0
A18: Terrains - immeuble de placement | J18: =D18+E18+F18+G18-H18-I18 -> 0
A19: Bâtiments hors immeuble de placement | J19: =D19+E19+F19+G19-H19-I19 -> 0
A20: Bâtiments - immeuble de placement | J20: =D20+E20+F20+G20-H20-I20 -> 0
A21: Aménagements, agencements et installations | J21: =D21+E21+F21+G21-H21-I21 -> 0
A22: Matériel, mobilier et actifs biologiques | I22: 0 | J22: =D22+E22+F22+G22-H22-I22 -> 0
A23: Matériel de transport | J23: =D23+E23+F23+G23-H23-I23 -> 0
A24: AVANCES ET ACOMPTES VERSES SUR IMMOBILISATIONS | J24: =D24+E24+F24+G24-H24-I24 -> 0
A25: Avances et acomptes sur immobilisations incorporelles | J25: =D25+E25+F25+G25-H25-I25 -> 0
A26: Avances et acomptes sur immobilisations corporelles | J26: =D26+E26+F26+G26-H26-I26 -> 0
A27: IMMOBILISATIONS FINANCIERES | D27: =SUM(D28:D29) -> 0 | E27: =SUM(E28:E29) -> 0 | F27: =SUM(F28:F29) -> 0 | G27: =SUM(G28:G29) -> 0 | H27: =SUM(H28:H29) -> 0 | I27: =SUM(I28:I29) -> 0 | J27: =D27+E27+F27+G27-H27-I27 -> 0
A28: Titres de participation | J28: =D28+E28+F28+G28-H28-I28 -> 0
A29: Autres immobilisations financières | J29: =D29+E29+F29+G29-H29-I29 -> 0
A30: TOTAL GENERAL | D30: =D11+D16+ D24 +D27 -> 0 | E30: =E11+E16+ E24 +E27 -> 0 | F30: =F11+F16+ F24 +F27 -> 0 | G30: =G11+G16+ G24 +G27 -> 0 | H30: =H11+H16+ H24 +H27 -> 0 | I30: =I11+I16+ I24 +I27 -> 0 | J30: =J11+J16+ J24 +J27 -> 0
A31: Commentaire :
A32: ● Toute variation significative doit être commentée. | E32: ● Indiquer les créances du groupe avec nature et date d'échéance.
A33: ● Détailler les éléments constitutifs du fonds commercial et indiquer la date d'acquisition. | E33: ● Pour les banques, DAT indiquer le nom de la banque le montant et la date d'échéance.
A34: ● Pour l'immobilisation incorporelle relative à la concession faire un descriptif de l'accord. | E34: ● Pour les frais de développement, donner toutes les informations mentionnées dans la partie Opérations et problèmes spécifiques.
A35: ● Indiquer : | E35: ● Donner le détail des produits et charges liés aux immeubles de placement.
A36: - la nature de la créance ;
A37: - la durée de la concession ;
A38: - l'échéance.

Sheet NOTE 3B
A1: - 0 -
K2: NOTE 3B SYSTEME NORMAL
A3: Dénomination sociale de l'entité : | C3: ='NOTE 1'!C3 -> 0
A4: Adresse : | B4: ='NOTE 1'!B4 -> 0 | K4: Sigle usuel : | L4: ='NOTE 1'!I4 -> 0
A5: N° IFU : | C5: ='NOTE 1'!C5 -> 0 | H5: Exercice clos le : | I5: ='NOTE 1'!G5 -> 0 | K5: Durée (en mois) : | L5: ='NOTE 1'!I5 -> 0
A6: N° de télédéclarant (NES): | C6: ='NOTE 1'!C6 -> 0
A7: NOTE 3B : BIENS PRIS EN LOCATION ACQUISITION
A8: SITUATIONS ET MOUVEMENTS | F8: A | G8: AUGMENTATIONS B | J8: DIMINUTIONS C | L8: D = A + B - C
E9: NATURE DU CONTRAT (I ; M ; A) [1] | F9: MONTANT BRUT A L'OUVERTURE DE L'EXERCICE | G9: Acquisitions Apports Créations | H9: Virements de poste à poste | I9: Suite à une réévaluation pratiquée au cours de l'exercice | J9: Cessions Scissions Hors service | K9: Virements de poste à poste | L9: MONTANT BRUT A LA CLOTURE DE L'EXERCICE
A10: RUBRIQUES
A11: Terrains | L11: =F11+G11+H11+I11-J11-K11 -> 0
A12: Bâtiments | L12: =F12+G12+H12+I12-J12-K12 -> 0
A13: Matériel, mobilier | L13: =F13+G13+H13+I13-J13-K13 -> 0
A14: Matériel de transport | L14: =F14+G14+H14+I14-J14-K14 -> 0
A15: TOTAL IMMOBILISATIONS EN LOCATION-ACQUISITION | F15: =SUM(F11:F14) -> 0 | G15: =SUM(G11:G14) -> 0 | H15: =SUM(H11:H14) -> 0 | I15: =SUM(I11:I14) -> 0 | J15: =SUM(J11:J14) -> 0 | K15: =SUM(K11:K14) -> 0 | L15: =SUM(L11:L14) -> 0
A16: [1] I : Crédit-bail immobilier ; M : Crédit-bail mobilier ; A : Autres contrats (dédoubler le poste si montants
A17: Commentaire:
A18: ● Indiquer la nature du bien, le nom du bailleur et la durée du bail.

Sheet NOTE 3C
A1: - 0 -
N2: NOTE 3C SYSTEME NORMAL
A3: Dénomination sociale de l'entité : | C3: ='NOTE 1'!C3 -> 0
A4: Adresse : | B4: ='NOTE 1'!B4 -> 0 | L4: Sigle usuel : | N4: ='NOTE 1'!I4 -> 0
A5: N° IFU : | C5: ='NOTE 1'!C5 -> 0 | H5: Exercice clos le : | J5: ='NOTE 1'!G5 -> 0 | L5: Durée (en mois) : | N5: ='NOTE 1'!I5 -> 0
A6: N° de télédéclarant (NES): | C6: ='NOTE 1'!C6 -> 0
A7: NOTE 3C : IMMOBILISATIONS (AMORTISSEMENTS)
A8: SITUATIONS ET MOUVEMENTS | D8: A | F8: B | H8: C | L8: D | N8: E = A + B - C - D
D9: AMORTISSEMENTS CUMULES A L'OUVERTURE DE L'EXERCICE | F9: AUGMENTATIONS: | H9: DIMINUTIONS : | L9: Virements de poste à poste | N9: CUMUL DES AMORTISSEMENTS A LA CLOTURE DE L'EXERCICE
A10: RUBRIQUES | F10: DOTATIONS DE L'EXERCICE | H10: Amortissements relatifs aux éléments sortis de l'actif | J10: Reprises d'amortissements
A11: Frais de développement et de prospection | N11: =D11+F11-H11-J11-L11 -> 0
A12: Brevets, licences, logiciels et droits similaires | N12: =D12+F12-H12-J12-L12 -> 0
A13: Fonds commercial et droit au bail | N13: =D13+F13-H13-J13-L13 -> 0
A14: Autres immobilisations incorporelles | N14: =D14+F14-H14-J14-L14 -> 0
A15: IMMOBILISATIONS INCORPORELLES | D15: =SUM(D11:E14) -> 0 | F15: =SUM(F11:G14) -> 0 | H15: =SUM(H11:I14) -> 0 | J15: =SUM(J11:K14) -> 0 | L15: =SUM(L11:M14) -> 0 | N15: =SUM(N11:O14) -> 0
A16: Terrains hors immeuble de placement | N16: =D16+F16-H16-J16-L16 -> 0
A17: Terrains - immeuble de placement | N17: =D17+F17-H17-J17-L17 -> 0
A18: Bâtiments hors immeuble de placement | N18: =D18+F18-H18-J18-L18 -> 0
A19: Bâtiments - immeuble de placement | N19: =D19+F19-H19-J19-L19 -> 0
A20: Aménagements, agencements et installations | N20: =D20+F20-H20-J20-L20 -> 0
A21: Matériel, mobilier et actifs biologiques | N21: =D21+F21-H21-J21-L21 -> 0
A22: Matériel de transport | N22: =D22+F22-H22-J22-L22 -> 0
A23: IMMOBILISATIONS CORPORELLES | D23: =SUM(D16:E22) -> 0 | F23: =SUM(F16:G22) -> 0 | H23: =SUM(H16:I22) -> 0 | J23: =SUM(J16:K22) -> 0 | L23: =SUM(L16:M22) -> 0 | N23: =SUM(N16:O22) -> 0
A24: TOTAL GENERAL | D24: =D15+D23 -> 0 | F24: =F15+F23 -> 0 | H24: =H15+H23 -> 0 | J24: =J15+J23 -> 0 | L24: =L15+L23 -> 0 | N24: =N15+N23 -> 0
A25: Commentaire :
A26: ● Indiquer
A27: - les modes d'amortissement utilisés ;
A28: - la durée d'utilité ou les taux d'amortissements utilisés.

Sheet NOTE 3C BIS
A1: - 0 -
J2: NOTE 3C BIS SYSTEME NORMAL
A3: Dénomination sociale de l'entité : | C3: ='NOTE 1'!C3 -> 0
A4: Adresse : | B4: ='NOTE 1'!B4 -> 0 | J4: Sigle usuel : | K4: ='NOTE 1'!I4 -> 0
A5: N° IFU : | C5: ='NOTE 1'!C5 -> 0 | E5: Exercice clos le : | G5: ='NOTE 1'!G5 -> 0 | J5: Durée (mois) : | K5: ='NOTE 1'!I5 -> 0
A6: N° de télédéclarant (NES): | C6: ='NOTE 1'!C6 -> 0
A7: NOTE 3C BIS : IMMOBILISATIONS (DEPRECIATIONS)
A8: SITUATIONS ET MOUVEMENTS | D8: A | F8: B | H8: C | J8: D = A + B - C
D9: DEPRECIATIONS CUMULES A L'OUVERTURE DE L'EXERCICE | F9: AUGMENTATIONS: DOTATIONS DE L'EXERCICE | H9: DIMINUTIONS : REPRISES DE L'EXERCICE | J9: CUMUL DES DEPRECIATIONS A LA CLOTURE DE L'EXERCICE
A10: RUBRIQUES
A11: Frais de développement et de prospection | J11: =D11+F11-H11 -> 0
A12: Brevets, licences, logiciels et droits similaires | J12: =D12+F12-H12 -> 0
A13: Fonds commercial et droit au bail | J13: =D13+F13-H13 -> 0
A14: Autres immobilisations incorporelles | J14: =D14+F14-H14 -> 0
A15: IMMOBILISATIONS INCORPORELLES | D15: =SUM(D11:E14) -> 0 | F15: =SUM(F11:G14) -> 0 | H15: =SUM(H11:I14) -> 0 | J15: =SUM(J11:K14) -> 0
A16: Terrains hors immeuble de placement | J16: =D16+F16-H16 -> 0
A17: Terrains - immeuble de placement | J17: =D17+F17-H17 -> 0
A18: Bâtiments hors immeuble de placement | J18: =D18+F18-H18 -> 0
A19: Bâtiments - immeuble de placement | J19: =D19+F19-H19 -> 0
A20: Aménagements, agencements et installations | J20: =D20+F20-H20 -> 0
A21: Matériel, mobilier et actifs biologiques | J21: =D21+F21-H21 -> 0
A22: Matériel de transport | J22: =D22+F22-H22 -> 0
A23: IMMOBILISATIONS CORPORELLES | D23: =SUM(D16:E22) -> 0 | F23: =SUM(F16:G22) -> 0 | H23: =SUM(H16:I22) -> 0 | J23: =SUM(J16:K22) -> 0
A24: TOTAL GENERAL | D24: =D15+D23 -> 0 | F24: =F15+F23 -> 0 | H24: =H15+H23 -> 0 | J24: =J15+J23 -> 0
A25: Commentaire :
A26: ● Indiquer les événements et circonstances qui ont conduit à la dépréciation et à la reprise.

Sheet NOTE 3D
A1: - 0 -
G2: NOTE 3D SYSTEME NORMAL
A3: Dénomination sociale de l'entité : | C3: ='NOTE 1'!C3 -> 0
A4: Adresse : | B4: ='NOTE 1'!B4 -> 0 | G4: Sigle usuel : | H4: ='NOTE 1'!I4 -> 0
A5: N° IFU : | C5: ='NOTE 1'!C5 -> 0 | D5: Exercice clos le : | E5: ='NOTE 1'!G5 -> 0 | G5: Durée (en mois) : | H5: ='NOTE 1'!I5 -> 0
A6: N° de télédéclarant (NES): | C6: ='NOTE 1'!C6 -> 0
A7: NOTE 3D : IMMOBILISATIONS (PLUS-VALUES ET MOINS- VALUES DE CESSION)
A8: SITUATIONS ET MOUVEMENTS | D8: MONTANT BRUT | E8: AMORTISSEMENTS PRATIQUES | F8: VALEUR COMPTABLE NETTE | G8: PRIX DE CESSION | H8: PLUS-VALUE OU MOINS-VALUE
A9: RUBRIQUES | D9: A | E9: B | F9: C = A - B | G9: D | H9: E = D - C
A10: Frais de développement et de prospection | F10: =D10-E10 -> 0 | H10: =G10-F10 -> 0
A11: Brevets, licences, logiciels et droits similaires | F11: =D11-E11 -> 0 | H11: =G11-F11 -> 0
A12: Fonds commercial et droit au bail | F12: =D12-E12 -> 0 | H12: =G12-F12 -> 0
A13: Autres immobilisations incorporelles | F13: =D13-E13 -> 0 | H13: =G13-F13 -> 0
A14: IMMOBILISATIONS INCORPORELLES | D14: =SUM(D10:D13) -> 0 | E14: =SUM(E10:E13) -> 0 | F14: =SUM(F10:F13) -> 0 | G14: =SUM(G10:G13) -> 0 | H14: =SUM(H10:H13) -> 0
A15: Terrains | F15: =D15-E15 -> 0 | H15: =G15-F15 -> 0
A16: Bâtiments | F16: =D16-E16 -> 0 | H16: =G16-F16 -> 0
A17: Aménagements, agencements et installations | F17: =D17-E17 -> 0 | H17: =G17-F17 -> 0
A18: Matériel, mobilier et actifs biologiques | F18: =D18-E18 -> 0 | H18: =G18-F18 -> 0
A19: Matériel de transport | F19: =D19-E19 -> 0 | H19: =G19-F19 -> 0
A20: IMMOBILISATIONS CORPORELLES | D20: =SUM(D15:D19) -> 0 | E20: =SUM(E15:E19) -> 0 | F20: =SUM(F15:F19) -> 0 | G20: =SUM(G15:G19) -> 0 | H20: =SUM(H15:H19) -> 0
A21: Titres de participations | F21: =D21-E21 -> 0 | H21: =G21-F21 -> 0
A22: Autres immobilisations financières | F22: =D22-E22 -> 0 | H22: =G22-F22 -> 0
A23: IMMOBILISATIONS FINANCIERES | D23: =SUM(D21:D22) -> 0 | E23: =SUM(E21:E22) -> 0 | F23: =SUM(F21:F22) -> 0 | G23: =SUM(G21:G22) -> 0 | H23: =SUM(H21:H22) -> 0
A24: TOTAL GENERAL | D24: =D14+D20+D23 -> 0 | E24: =E14+E20+E23 -> 0 | F24: =F14+F20+F23 -> 0 | G24: =G14+G20+G23 -> 0 | H24: =H14+H20+H23 -> 0
A25: Commentaire :
A26: ● Mentionner la justification de la cession ainsi que la date d'acquisition et la date de sortie.

Sheet NOTE 3E
A1: - 0 -
H2: NOTE 3E SYSTEME NORMAL
A3: Dénomination sociale de l'entité : | C3: ='NOTE 1'!C3 -> 0
A4: Adresse : | B4: ='NOTE 1'!B4 -> 0 | H4: Sigle usuel : | I4: ='NOTE 1'!I4 -> 0
A5: N° IFU : | C5: ='NOTE 1'!C5 -> 0 | D5: Exercice clos le : | E5: ='NOTE 1'!G5 -> 0 | H5: Durée (en mois) : | I5: ='NOTE 1'!I5 -> 0
A6: N° de télédéclarant (NES): | C6: ='NOTE 1'!C6 -> 0
A7: NOTE 3E : INFORMATIONS SUR LES REEVALUATIONS EFFECTUEES PAR L'ENTITE
A8: Nature et date des réévaluations :
A10: Eléments réévalués par postes du bilan | F10: Montants en coûts historiques | G10: Montant réévalués | H10: Ecarts de réévaluation | I10: Amortissements supplémentaires
A18: TOTAL GENERAL | F18: =SUM(F11:F17) -> 0 | G18: =SUM(G11:G17) -> 0 | H18: =SUM(H11:H17) -> 0 | I18: =SUM(I11:I17) -> 0
A19: Méthode de réévaluation utilisée :
A21: Traitement fiscal de l'écart de réévaluation et des amortissements supplémentaires :
A23: Montant de l'écart incorporé au capital :

Sheet NOTE 4
A1: - 0 -
J2: NOTE 4 SYSTEME NORMAL
A3: Dénomination sociale de l'entité : | C3: ='NOTE 1'!C3 -> 0
A4: Adresse : | B4: ='NOTE 1'!B4 -> 0 | I4: Sigle usuel : | J4: ='NOTE 1'!I4 -> 0
A5: N° IFU : | C5: ='NOTE 1'!C5 -> 0 | F5: Exercice clos le : | G5: ='NOTE 1'!G5 -> 0 | I5: Durée (en mois) : | J5: ='NOTE 1'!I5 -> 0
A6: N° de télédéclarant (NES): | C6: ='NOTE 1'!C6 -> 0
A7: NOTE 4 : IMMOBILISATIONS FINANCIERES
A8: Libellés | F8: Année N | G8: Année N-1 | H8: Variation en % | I8: Créances à un an au plus | J8: Créances à plus d'un an et à deux ans au plus | K8: Créances à plus de deux ans
A9: Titres de participation | H9: =IF(G9,(F9-G9)/ABS(G9),IF(ISBLANK(G9),"",IF(F9,IF( F9 > 0,1,-1),"")))
A10: Prêts et créances | H10: =IF(G10,(F10-G10)/ABS(G10),IF(ISBLANK(G10),"",IF(F10,IF( F10 > 0,1,-1),"")))
A11: Prêt au personnel | H11: =IF(G11,(F11-G11)/ABS(G11),IF(ISBLANK(G11),"",IF(F11,IF( F11 > 0,1,-1),"")))
A12: Créances sur l'état | H12: =IF(G12,(F12-G12)/ABS(G12),IF(ISBLANK(G12),"",IF(F12,IF( F12 > 0,1,-1),"")))
A13: Titres immobilisés | H13: =IF(G13,(F13-G13)/ABS(G13),IF(ISBLANK(G13),"",IF(F13,IF( F13 > 0,1,-1),"")))
A14: Dépôts et cautionnements | H14: =IF(G14,(F14-G14)/ABS(G14),IF(ISBLANK(G14),"",IF(F14,IF( F14 > 0,1,-1),"")))
A15: Intérêts courus | H15: =IF(G15,(F15-G15)/ABS(G15),IF(ISBLANK(G15),"",IF(F15,IF( F15 > 0,1,-1),"")))
A16: Créances rattachées à des avances et participations à des GIE | H16: =IF(G16,(F16-G16)/ABS(G16),IF(ISBLANK(G16),"",IF(F16,IF( F16 > 0,1,-1),"")))
A17: Immobilisations financières diverses | H17: =IF(G17,(F17-G17)/ABS(G17),IF(ISBLANK(G17),"",IF(F17,IF( F17 > 0,1,-1),"")))
A18: TOTAL BRUT | F18: =SUM(F9:F15) -> 0 | G18: =SUM(G9:G15) -> 0 | H18: =IF(G18,(F18-G18)/G18,IF(ISBLANK(G18),"",IF(F18,1,""))) | I18: =SUM(I9:I15) -> 0 | J18: =SUM(J9:J15) -> 0 | K18: =SUM(K9:K15) -> 0
A19: Dépréciations des titres de participation | H19: =IF(G19,(F19-G19)/ABS(G19),IF(ISBLANK(G19),"",IF(F19,IF( F19 > 0,1,-1),"")))
A20: Dépréciations des autres immobilisations financières | H20: =IF(G20,(F20-G20)/ABS(G20),IF(ISBLANK(G20),"",IF(F20,IF( F20 > 0,1,-1),"")))
A21: TOTAL NET DE DEPRECIATION | F21: =F18+F19+F20 -> 0 | G21: =G18+G19+G20 -> 0 | H21: =IF(G21,(F21-G21)/G21,IF(ISBLANK(G21),"",IF(F21,1,"")))
A23: Liste des filiales et participations :
A24: Dénomination sociale | E24: Localisation (ville / pays) | G24: Valeur d'acquisition | H24: % Détenu | I24: Montant des capitaux propres filiale | J24: Résultat dernier exercice filiale (1) | K24: Part de bénéfice reçue de la filiale (2)
A31: (1): Préciser s'il s'agit du résultat de l'exercice N ou du résultat de l'exercice N-1 | E31: (2): S'il s'agit du résultat de l'exercice n-1, renseigner la colonne "part du bénéfice reçue de la filiale"
A32: Commentaire :
A33: ● Justifier toute variation significative. | F33: ● Indiquer le nombre et la date d'acquisition des actions ou parts propres.
A34: ● Commenter toutes les créances anciennes. | F34: ● Dépréciation : indiquer les évènements et les circonstances qui ont motivé la dépréciation ou la reprise.
A35: ● Pour les créances relatives à la concession, faire un descriptif de l'accord.
A36: ● Indiquer :
A37: - la nature de la créance ;
A38: - la durée de la concession ;
A39: - l'échéance.

Sheet NOTE 5
A1: - 0 -
H2: NOTE 5 SYSTEME NORMAL
A3: Dénomination sociale de l'entité : | C3: ='NOTE 1'!C3 -> 0
A4: Adresse : | B4: ='NOTE 1'!B4 -> 0 | H4: Sigle usuel : | I4: ='NOTE 1'!I4 -> 0
A5: N° IFU : | C5: ='NOTE 1'!C5 -> 0 | E5: Exercice clos le : | F5: ='NOTE 1'!G5 -> 0 | H5: Durée (en mois) : | I5: ='NOTE 1'!I5 -> 0
A6: N° de télédéclarant (NES): | C6: ='NOTE 1'!C6 -> 0
A7: NOTE 5 : ACTIF CIRCULANT ET DETTES CIRCULANTES HAO
A8: ACTIF CIRCULANT HAO
A9: Libellés | E9: Année N | G9: Année N-1 | I9: Variation en %
A10: Créances sur cessions d'immobilisations | I10: =IF(G10,(E10-G10)/G10,IF(ISBLANK(G10),"",IF(E10,IF( E10 > 0,1,-1),"")))
A11: Autres créances hors activités ordinaires | I11: =IF(G11,(E11-G11)/G11,IF(ISBLANK(G11),"",IF(E11,IF( E11 > 0,1,-1),"")))
A12: TOTAL BRUT | E12: =SUM(E10:F11) -> 0 | G12: =SUM(G10:H11) -> 0 | I12: =IF(G12,(E12-G12)/G12,IF(ISBLANK(G12),"",IF(E12,IF( E12 > 0,1,-1),"")))
A13: Dépréciations des créances HAO | I13: =IF(G13,(E13-G13)/G13,IF(ISBLANK(G13),"",IF(E13,IF( E13 > 0,1,-1),"")))
A14: TOTAL NET DE DEPRECIATIONS | E14: =E12+E13 -> 0 | G14: =G12+G13 -> 0 | I14: =IF(G14,(E14-G14)/G14,IF(ISBLANK(G14),"",IF(E14,IF( E14 > 0,1,-1),"")))
A15: Commentaire:
A16: • Commenter toute variation significative.
A17: • Dépréciation : indiquer les évènements et les circonstances qui ont motivé la dépréciation ou la reprise.
A19: DETTES CIRCULANTES HAO
A21: Libellés | E21: Année N | G21: Année N-1 | I21: Variation en %
A22: Fournisseurs d'investissements | I22: =IF(G22,(E22-G22)/G22,IF(ISBLANK(G22),"",IF(E22,IF( E22 > 0,1,-1),"")))
A23: Fournisseurs d'investissements effets à payer | I23: =IF(G23,(E23-G23)/G23,IF(ISBLANK(G23),"",IF(E23,IF( E23 > 0,1,-1),"")))
A24: Versements restant à effectuer sur titres de participation et titres immobilisés non libérés | I24: =IF(G24,(E24-G24)/G24,IF(ISBLANK(G24),"",IF(E24,IF( E24 > 0,1,-1),"")))
A25: Autres dettes hors activités ordinaires | I25: =IF(G25,(E25-G25)/G25,IF(ISBLANK(G25),"",IF(E25,IF( E25 > 0,1,-1),"")))
A26: TOTAL | E26: =SUM(E22:F25) -> 0 | G26: =SUM(G22:H25) -> 0 | I26: =IF(G26,(E26-G26)/G26,IF(ISBLANK(G26),"",IF(E26,IF( E26 > 0,1,-1),"")))
A27: Commentaire:
A28: ● Indiquer la date de cession et la nature de l'immobilisation achetée et/ou cédée.
A29: ● Expliciter toute variation significative.

Sheet NOTE 6
A1: - 0 -
I2: NOTE 6 SYSTEME NORMAL
A3: Dénomination sociale de l'entité : | C3: ='NOTE 1'!C3 -> 0
A4: Adresse : | B4: ='NOTE 1'!B4 -> 0 | I4: Sigle usuel : | J4: ='NOTE 1'!I4 -> 0
A5: N° IFU : | C5: ='NOTE 1'!C5 -> 0 | E5: Exercice clos le : | F5: ='NOTE 1'!G5 -> 0 | I5: Durée (en mois) : | J5: ='NOTE 1'!I5 -> 0
A6: N° de télédéclarant (NES): | C6: ='NOTE 1'!C6 -> 0
A7: NOTE 6 : STOCKS ET EN COURS (1)
A8: Libellés | E8: Année N | G8: Année N-1 | I8: Variation de stock en valeur absolue | J8: Variation en %
A9: Marchandises | I9: =ABS(E9-G9) -> 0 | J9: =IF(G9,(E9-G9)/G9,IF(ISBLANK(G9),"",IF(E9,IF( E9 > 0,1,-1),"")))
A10: Matières premières et fournitures liées | I10: =ABS(E10-G10) -> 0 | J10: =IF(G10,(E10-G10)/G10,IF(ISBLANK(G10),"",IF(E10,IF( E10 > 0,1,-1),"")))
A11: Autres approvisionnements | I11: =ABS(E11-G11) -> 0 | J11: =IF(G11,(E11-G11)/G11,IF(ISBLANK(G11),"",IF(E11,IF( E11 > 0,1,-1),"")))
A12: Produits en cours | I12: =ABS(E12-G12) -> 0 | J12: =IF(G12,(E12-G12)/G12,IF(ISBLANK(G12),"",IF(E12,IF( E12 > 0,1,-1),"")))
A13: Services en cours | I13: =ABS(E13-G13) -> 0 | J13: =IF(G13,(E13-G13)/G13,IF(ISBLANK(G13),"",IF(E13,IF( E13 > 0,1,-1),"")))
A14: Produits finis | I14: =ABS(E14-G14) -> 0 | J14: =IF(G14,(E14-G14)/G14,IF(ISBLANK(G14),"",IF(E14,IF( E14 > 0,1,-1),"")))
A15: Produits intermédiaires | I15: =ABS(E15-G15) -> 0 | J15: =IF(G15,(E15-G15)/G15,IF(ISBLANK(G15),"",IF(E15,IF( E15 > 0,1,-1),"")))
A16: Stocks en cours de route, en consignation ou en dépôt | I16: =ABS(E16-G16) -> 0 | J16: =IF(G16,(E16-G16)/G16,IF(ISBLANK(G16),"",IF(E16,IF( E16 > 0,1,-1),"")))
A17: TOTAL BRUT STOCKS ET EN COURS | E17: =SUM(E9:F16) -> 0 | G17: =SUM(G9:H16) -> 0 | I17: =ABS(E17-G17) -> 0 | J17: =IF(G17,(E17-G17)/G17,IF(ISBLANK(G17),"",IF(E17,IF( E17 > 0,1,-1),"")))
A18: Dépréciations des stocks | I18: =ABS(E18-G18) -> 0 | J18: =IF(G18,(E18-G18)/G18,IF(ISBLANK(G18),"",IF(E18,IF( E18 > 0,1,-1),"")))
A19: TOTAL NET DE DEPRECIATIONS | E19: =E17+E18 -> 0 | G19: =G17+G18 -> 0 | I19: =ABS(E19-G19) -> 0 | J19: =IF(G19,(E19-G19)/G19,IF(ISBLANK(G19),"",IF(E19,IF( E19 > 0,1,-1),"")))
A20: (1) Les stocks H.A.O. seront inscrits dans l'actif circulant H.A.O. que lorsque leur montant total est significatif (supérieur à 5 % du total de l'actif circulant).
A21: Commentaire :
A22: ● Indiquer la date de prise d'inventaire et décrire brièvement la procédure, les méthodes comptables adoptées pour évaluer le stock.
A23: ● Commenter toute variation significative des stocks.
A24: ● Indiquer le détail des stocks dépréciés et les évènements et circonstances qui ont conduit à la dépréciation et à la reprise.

Sheet NOTE 7
A1: - 0 -
I2: NOTE 7 SYSTEME NORMAL
A3: Dénomination sociale de l'entité : | C3: ='NOTE 1'!C3 -> 0
A4: Adresse : | B4: ='NOTE 1'!B4 -> 0 | I4: Sigle usuel : | J4: ='NOTE 1'!I4 -> 0
A5: N° IFU : | C5: ='NOTE 1'!C5 -> 0 | F5: Exercice clos le : | G5: ='NOTE 1'!G5 -> 0 | I5: Durée (en mois) : | J5: ='NOTE 1'!I5 -> 0
A6: N° de télédéclarant (NES): | C6: ='NOTE 1'!C6 -> 0
A7: NOTE 7 : CLIENTS
A8: Libellés | E8: Année N | F8: Année N-1 | G8: Variation en % | H8: Créances à un an au plus | I8: Créances à plus d'un an et à deux ans au plus | J8: Créances à plus de deux ans
A9: Clients (hors réserves de propriété et Groupe) | G9: =IF(F9,(E9-F9)/F9,IF(ISBLANK(F9),"",IF(E9,IF( E9 > 0,1,-1),"")))
A10: Clients effets à recevoir (hors réserves de propriété et groupe) | G10: =IF(F10,(E10-F10)/F10,IF(ISBLANK(F10),"",IF(E10,IF( E10 > 0,1,-1),"")))
A11: Clients avec réserves de propriété | G11: =IF(F11,(E11-F11)/F11,IF(ISBLANK(F11),"",IF(E11,IF( E11 > 0,1,-1),"")))
A12: Clients et effets à recevoir Groupe | G12: =IF(F12,(E12-F12)/F12,IF(ISBLANK(F12),"",IF(E12,IF( E12 > 0,1,-1),"")))
A13: Créances sur cession d'immobilisations | G13: =IF(F13,(E13-F13)/F13,IF(ISBLANK(F13),"",IF(E13,IF( E13 > 0,1,-1),"")))
A14: Clients effets escomptés et non échus | G14: =IF(F14,(E14-F14)/F14,IF(ISBLANK(F14),"",IF(E14,IF( E14 > 0,1,-1),"")))
A15: Créances litigieuses ou douteuses | G15: =IF(F15,(E15-F15)/F15,IF(ISBLANK(F15),"",IF(E15,IF( E15 > 0,1,-1),"")))
A16: Clients produits à recevoir | G16: =IF(F16,(E16-F16)/F16,IF(ISBLANK(F16),"",IF(E16,IF( E16 > 0,1,-1),"")))
A17: TOTAL BRUT CLIENTS | E17: =SUM(E9:E16) -> 0 | F17: =SUM(F9:F16) -> 0 | G17: =IF(F17,(E17-F17)/F17,IF(ISBLANK(F17),"",IF(E17,IF( E17 > 0,1,-1),""))) | H17: =SUM(H9:H16) -> 0 | I17: =SUM(I9:I16) -> 0 | J17: =SUM(J9:J16) -> 0
A18: Dépréciations des comptes clients | G18: =IF(F18,(E18-F18)/F18,IF(ISBLANK(F18),"",IF(E18,IF( E18 > 0,1,-1),"")))
A19: TOTAL NET DE DEPRECIATIONS | E19: =E17-E18 -> 0 | F19: =F17-F18 -> 0 | G19: =IF(F19,(E19-F19)/F19,IF(ISBLANK(F19),"",IF(E19,IF( E19 > 0,1,-1),"")))
A20: Clients, avances reçues hors groupe | G20: =IF(F20,(E20-F20)/F20,IF(ISBLANK(F20),"",IF(E20,IF( E20 > 0,1,-1),"")))
A21: Clients, avances reçues groupe | G21: =IF(F21,(E21-F21)/F21,IF(ISBLANK(F21),"",IF(E21,IF( E21 > 0,1,-1),"")))
A22: Autres clients créditeurs | G22: =IF(F22,(E22-F22)/F22,IF(ISBLANK(F22),"",IF(E22,IF( E22 > 0,1,-1),"")))
A23: TOTAL CLIENTS CREDITEURS | E23: =SUM(E20:E22) -> 0 | F23: =SUM(F20:F22) -> 0 | G23: =IF(F23,(E23-F23)/F23,IF(ISBLANK(F23),"",IF(E23,IF( E23 > 0,1,-1),""))) | H23: =SUM(H20:H22) -> 0 | I23: =SUM(I20:I22) -> 0 | J23: =SUM(J20:J22) -> 0
A24: Commentaire :
A25: ● Commenter toutes variations significatives.
A26: ● Indiquer pour les créances du groupe, le nom de la société du groupe et le % de titres détenues.
A27: ● Commenter les créances anciennes.
A28: ● Indiquer les événements et circonstances qui ont conduit à la dépréciation et à la reprise.

Sheet NOTE 8
A1: - 0 -
I2: NOTE 8 SYSTEME NORMAL
A3: Dénomination sociale de l'entité : | C3: ='NOTE 1'!C3 -> 0
A4: Adresse : | B4: ='NOTE 1'!B4 -> 0 | I4: Sigle usuel : | J4: ='NOTE 1'!I4 -> 0
A5: N° IFU : | C5: ='NOTE 1'!C5 -> 0 | F5: Exercice clos le : | G5: ='NOTE 1'!G5 -> 0 | I5: Durée (en mois) : | J5: ='NOTE 1'!I5 -> 0
A6: N° de télédéclarant (NES): | C6: ='NOTE 1'!C6 -> 0
A7: NOTE 8 : AUTRES CREANCES
A8: Libellés | E8: Année N | F8: Année N-1 | G8: Variation en % | H8: Créances à un an au plus | I8: Créances à plus d'un an et à deux ans au plus | J8: Créances à plus de deux ans
A9: Personnel | G9: =IF(F9,(E9-F9)/F9,IF(ISBLANK(F9),"",IF(E9,IF( E9 > 0,1,-1),"")))
A10: Organismes sociaux | G10: =IF(F10,(E10-F10)/F10,IF(ISBLANK(F10),"",IF(E10,IF( E10 > 0,1,-1),"")))
A11: Etat et Collectivités publiques | G11: =IF(F11,(E11-F11)/F11,IF(ISBLANK(F11),"",IF(E11,IF( E11 > 0,1,-1),"")))
A12: Organismes internationaux | G12: =IF(F12,(E12-F12)/F12,IF(ISBLANK(F12),"",IF(E12,IF( E12 > 0,1,-1),"")))
A13: Apporteurs, associés et groupe | G13: =IF(F13,(E13-F13)/F13,IF(ISBLANK(F13),"",IF(E13,IF( E13 > 0,1,-1),"")))
A14: Compte transitoire ajustement spécial lié à la révision du SYSCOHADA (Voir Notes 8A & 8C) | G14: =IF(F14,(E14-F14)/F14,IF(ISBLANK(F14),"",IF(E14,IF( E14 > 0,1,-1),"")))
A15: Autres débiteurs divers | G15: =IF(F15,(E15-F15)/F15,IF(ISBLANK(F15),"",IF(E15,IF( E15 > 0,1,-1),"")))
A16: Comptes permanents non bloqués des établissements et des succursales | G16: =IF(F16,(E16-F16)/F16,IF(ISBLANK(F16),"",IF(E16,IF( E16 > 0,1,-1),"")))
A17: Comptes de liaison charges et produits | G17: =IF(F17,(E17-F17)/F17,IF(ISBLANK(F17),"",IF(E17,IF( E17 > 0,1,-1),"")))
A18: Comptes de liaison des sociétés en participation | G18: =IF(F18,(E18-F18)/F18,IF(ISBLANK(F18),"",IF(E18,IF( E18 > 0,1,-1),"")))
A19: TOTAL BRUT AUTRES CREANCES | E19: =SUM(E9:E18) -> 0 | F19: =SUM(F9:F18) -> 0 | G19: =IF(F19,(E19-F19)/F19,IF(ISBLANK(F19),"",IF(E19,IF( E19 > 0,1,-1),""))) | H19: =SUM(H9:H18) -> 0 | I19: =SUM(I9:I18) -> 0 | J19: =SUM(J9:J18) -> 0
A20: Dépréciations des autres créances | G20: =IF(F20,(E20-F20)/F20,IF(ISBLANK(F20),"",IF(E20,IF( E20 > 0,1,-1),"")))
A21: TOTAL NET DE DEPRECIATIONS | E21: =E19-E20 -> 0 | F21: =F19-F20 -> 0 | G21: =IF(F21,(E21-F21)/F21,IF(ISBLANK(F21),"",IF(E21,IF( E21 > 0,1,-1),"")))
A22: Commentaire :
A23: ● Justifier toute variation significative.
A24: ● Détailler les créances dont le montant est significatif.
A25: ● Justifier les créances anciennes.
A26: ● Indiquer les événements et circonstances qui ont conduit à la dépréciation et à la reprise.
A27: ● Compte transitoire ajustement spécial, indiquer le détail du compte et la durée restant pour l'apurement.

Sheet NOTE 8A
A1: - 0 -
I2: NOTE 8A SYSTEME NORMAL
A3: Dénomination sociale de l'entité : | C3: ='NOTE 1'!C3 -> 0
A4: Adresse : | B4: ='NOTE 1'!B4 -> 0 | I4: Sigle usuel : | J4: ='NOTE 1'!I4 -> 0
A5: N° d'identification fiscale : | C5: ='NOTE 1'!C5 -> 0 | F5: Exercice clos le : | G5: ='NOTE 1'!G5 -> 0 | I5: Durée (en mois) : | J5: ='NOTE 1'!I5 -> 0
A6: N° de télédéclarant (NTD): | C6: ='NOTE 1'!C6 -> 0
A7: NOTE 8A : TABLEAU D’ETALEMENT DES CHARGES IMMOBILISEES
A8: Libellés | E8: Frais d'établissement | G8: Charges à repartir sur plusieurs exercices | I8: Primes de remboursement des obligations
A9: Compte transitoire à solder: 4751 compte transitoire, ajustement lié à la révision du SYSCOHADA, compte-actif
A10: Montant global à étaler au 1er janvier 2018
A11: Durée d'étalement retenue
A12: Exercice 2018 | E12: Comptes | F12: Montants | G12: Comptes | H12: Montants | I12: Comptes | J12: Montants
E13: 60... | G13: 60... | I13: 6714
E14: 61... | G14: 61...
E15: 62... | G15: 62...
E16: 63... | G16: 63...
E22: ... | G22: ...
A23: Total exercice 2018
A24: Total exercice 2019
A25: Total exercice 2020
A26: Total exercice 2021
A27: Total exercice 2022
A28: TOTAL GENERAL | F28: =SUM(F23:F27) -> 0 | H28: =SUM(H23:H27) -> 0 | J28: =SUM(J23:J27) -> 0

Sheet NOTE 8B
A1: - 0 -
H2: NOTE 8B SYSTEME NORMAL
A3: Dénomination sociale de l'entité : | C3: ='NOTE 1'!C3 -> 0
A4: Adresse : | B4: ='NOTE 1'!B4 -> 0 | H4: Sigle usuel : | I4: ='NOTE 1'!I4 -> 0
A5: N° d'identification fiscale : | C5: ='NOTE 1'!C5 -> 0 | E5: Exercice clos le : | F5: ='NOTE 1'!G5 -> 0 | H5: Durée (en mois) : | I5: ='NOTE 1'!I5 -> 0
A6: N° de télédéclarant (NTD): | C6: ='NOTE 1'!C6 -> 0
A7: NOTE 8B : TABLEAU D’ETALEMENT DE PROVISIONS POUR CHARGES A REPARTIR
A8: LIBELLES | E8: PROVISIONS POUR CHARGES A REPARTIR
A9: Compte transitoire à solder: 4752 compte transitoire ajustement spécial lié à la révision du SYSCOHADA, compte-passif
A10: Montant global à étaler au 1er janvier 2018
A11: Durée d'étalement retenue
E12: Comptes | H12: Montants
E13: 791 Reprises de provisions et dépréciations d'exploitation
A14: Total exercice 2018
A15: Total exercice 2019
A16: Total exercice 2020
A17: Total exercice 2021
A18: Total exercice 2022
A19: TOTAL GENERAL | H19: =SUM(H14:I18) -> 0

Sheet NOTE 8C
A1: - 0 -
H2: NOTE 8C SYSTEME NORMAL
A3: Dénomination sociale de l'entité : | C3: ='NOTE 1'!C3 -> 0
A4: Adresse : | B4: ='NOTE 1'!B4 -> 0 | H4: Sigle usuel : | I4: ='NOTE 1'!I4 -> 0
A5: N° d'identification fiscale : | C5: ='NOTE 1'!C5 -> 0 | E5: Exercice clos le : | F5: ='NOTE 1'!G5 -> 0 | H5: Durée (en mois) : | I5: ='NOTE 1'!I5 -> 0
A6: N° de télédéclarant (NTD): | C6: ='NOTE 1'!C6 -> 0
A7: NOTE 8C : TABLEAU D’ETALEMENT DE PROVISIONS POUR ENGAGEMENTS DE RETAITE
A8: Libellés | E8: PROVISIONS POUR PENSIONS ET OBLIGATIONS SIMILAIRES
A9: Compte transitoire à solder: 4752 compte transitoire ajustement spécial lié à la révision du SYSCOHADA, compte-passif
A10: Montant global à étaler au 1er janvier 2018
A11: Durée d'étalement retenue
E12: Comptes | H12: Montants
E13: 6911 Dotation aux provisions pour risques et charges
A14: Total exercice 2018
A15: Total exercice 2019
A16: Total exercice 2020
A17: Total exercice 2021
A18: Total exercice 2022
A19: TOTAL GENERAL | H19: =SUM(H14:I18) -> 0

Sheet NOTE 9
A1: - 0 -
H2: NOTE 9 SYSTEME NORMAL
A3: Dénomination sociale de l'entité : | C3: ='NOTE 1'!C3 -> 0
A4: Adresse : | B4: ='NOTE 1'!B4 -> 0 | H4: Sigle usuel : | I4: ='NOTE 1'!I4 -> 0
A5: N° IFU : | C5: ='NOTE 1'!C5 -> 0 | E5: Exercice clos le : | F5: ='NOTE 1'!G5 -> 0 | H5: Durée (en mois) : | I5: ='NOTE 1'!I5 -> 0
A6: N° de télédéclarant (NES): | C6: ='NOTE 1'!C6 -> 0
A7: NOTE 9 : TITRES DE PLACEMENT
A8: Libellés | E8: Année N | G8: Année N-1 | I8: Variation en %
A9: Titres de trésor et bons de caisse à court terme | I9: =IF(G9,(E9-G9)/G9,IF(ISBLANK(G9),"",IF(E9,IF( E9 > 0,1,-1),"")))
A10: Actions | I10: =IF(G10,(E10-G10)/G10,IF(ISBLANK(G10),"",IF(E10,IF( E10 > 0,1,-1),"")))
A11: Obligations | I11: =IF(G11,(E11-G11)/G11,IF(ISBLANK(G11),"",IF(E11,IF( E11 > 0,1,-1),"")))
A12: Bons de souscription | I12: =IF(G12,(E12-G12)/G12,IF(ISBLANK(G12),"",IF(E12,IF( E12 > 0,1,-1),"")))
A13: Titres négociables hors régions | I13: =IF(G13,(E13-G13)/G13,IF(ISBLANK(G13),"",IF(E13,IF( E13 > 0,1,-1),"")))
A14: Intérêts courus | I14: =IF(G14,(E14-G14)/G14,IF(ISBLANK(G14),"",IF(E14,IF( E14 > 0,1,-1),"")))
A15: Autres valeurs assimilées | I15: =IF(G15,(E15-G15)/G15,IF(ISBLANK(G15),"",IF(E15,IF( E15 > 0,1,-1),"")))
A16: TOTAL BRUT TITRES | E16: =SUM(E9:F15) -> 0 | G16: =SUM(G9:H15) -> 0 | I16: =IF(G16,(E16-G16)/G16,IF(ISBLANK(G16),"",IF(E16,IF( E16 > 0,1,-1),"")))
A17: Dépréciations des titres | I17: =IF(G17,(E17-G17)/G17,IF(ISBLANK(G17),"",IF(E17,IF( E17 > 0,1,-1),"")))
A18: TOTAL NET DE DEPRECIATIONS | E18: =E16-E17 -> 0 | G18: =G16-G17 -> 0 | I18: =IF(G18,(E18-G18)/G18,IF(ISBLANK(G18),"",IF(E18,IF( E18 > 0,1,-1),"")))
A19: Commentaire:
A20: ● Justifier toute variation significative.
A21: ● Pour les titres cotés à une bourse de valeur : indiquer le nombre, le prix unitaire d'acquisition et le cours de la bourse au 31 décembre.
A22: ● Faire ressortir les actions ou parts propres et indiquer la date d'acquisition et le nombre de titres détenus.
A23: ● Indiquer les événements et circonstances qui ont conduit à la dépréciation et à la reprise.

Sheet NOTE 10
A1: - 0 -
H2: NOTE 10 SYSTEME NORMAL
A3: Dénomination sociale de l'entité : | C3: ='NOTE 1'!C3 -> 0
A4: Adresse : | B4: ='NOTE 1'!B4 -> 0 | H4: Sigle usuel : | I4: ='NOTE 1'!I4 -> 0
A5: N° IFU : | C5: ='NOTE 1'!C5 -> 0 | E5: Exercice clos le : | F5: ='NOTE 1'!G5 -> 0 | H5: Durée (en mois) : | I5: ='NOTE 1'!I5 -> 0
A6: N° de télédéclarant (NES): | C6: ='NOTE 1'!C6 -> 0
A7: NOTE 10 : VALEURS A ENCAISSER
A8: Libellés | E8: Année N | G8: Année N-1 | I8: Variation en %
A9: Effets à encaisser | I9: =IF(G9,(E9-G9)/G9,IF(ISBLANK(G9),"",IF(E9,IF( E9 > 0,1,-1),"")))
A10: Effets à l'encaissement | I10: =IF(G10,(E10-G10)/G10,IF(ISBLANK(G10),"",IF(E10,IF( E10 > 0,1,-1),"")))
A11: Chèques à encaisser | I11: =IF(G11,(E11-G11)/G11,IF(ISBLANK(G11),"",IF(E11,IF( E11 > 0,1,-1),"")))
A12: Chèques à l'encaissement | I12: =IF(G12,(E12-G12)/G12,IF(ISBLANK(G12),"",IF(E12,IF( E12 > 0,1,-1),"")))
A13: Cartes de crédit à encaisser | I13: =IF(G13,(E13-G13)/G13,IF(ISBLANK(G13),"",IF(E13,IF( E13 > 0,1,-1),"")))
A14: Autres valeurs à encaisser | I14: =IF(G14,(E14-G14)/G14,IF(ISBLANK(G14),"",IF(E14,IF( E14 > 0,1,-1),"")))
A15: TOTAL BRUT VALEURS A ENCAISSER | E15: =SUM(E9:F14) -> 0 | G15: =SUM(G9:H14) -> 0 | I15: =IF(G15,(E15-G15)/G15,IF(ISBLANK(G15),"",IF(E15,IF( E15 > 0,1,-1),"")))
A16: Dépréciations des valeurs à encaisser | I16: =IF(G16,(E16-G16)/G16,IF(ISBLANK(G16),"",IF(E16,IF( E16 > 0,1,-1),"")))
